Workbook
Name A: triangle!$A$1

Sheet Note
A1: IMPORTANT NOTE:
A3: From 17 December 2024, we have reweighted Labour Force Survey (LFS) estimates.
A4: The reweighted LFS estimates incorporate information on the size and composition of the UK population, based on 2022 mid-year estimates. For England, Wales and Northern Ireland they are projected forward using scaling factors from 2021-based National Population projections, published in January 2024. For Scotland they are projected forward using scaling factors from 2020-based National Population Projections, published in January 2023.
A5: Given time constraints, we were only able to reweight LFS data from January to March 2019 onwards. Therefore, this reweighting exercise created a discontinuity between December 2018 to February 2019 and January to March 2019 where there is a step change in LFS estimates. However, we have modelled the seasonally adjusted UK levels of employment, unemployment and economic inactivity by sex and age-band back to June to August 2011, to ensure that headline rates and levels by sex and age-band (datasets A02SA and A05SA) can be assessed without a discontinuity.
A6: Important note: Reweighting increased the levels of all labour market statuses but did not address issues surrounding increased LFS volatility, resulting from smaller achieved sample sizes.
A7: Estimates from January to March 2025 include the full effect of the improvements in LFS data collection and sampling methods introduced from January 2024. However, estimates may be subject to the effect of further ongoing improvements. An increased amount of volatility will remain in the LFS estimates from mid-2023 and throughout 2024, so we would advise additional caution when interpreting change involving those periods.
A8: We recommend using LFS estimates as part of our suite of labour market indicators, alongside Workforce Jobs, Claimant Count and Pay As You Earn Real Time Information (PAYE RTI) estimates.
A9: These are official statistics in development.
A10: For further information, please see our Impact of reweighting on Labour Force Survey key indicators article:
A11: https://www.ons.gov.uk/releases/impactofreweightingonlabourforcesurveykeyindicatorsdecember2024

Sheet triangle
B1: EMP05: Revisions triangle for UK Employment rate
B3: 1. UK Employment rate
B4: This spreadsheet provides a revisions analysis for the employment rate for those aged from 16 to 64. This series was first published in August 2010.
B6: Relating to Period (three months ending) | C6: 40330 | D6: 40360 | E6: 40391 | F6: 40422 | G6: 40452 | H6: 40483 | I6: 40513 | J6: 40544 | K6: 40575 | L6: 40603 | M6: 40634 | N6: 40664 | O6: 40695 | P6: 40725 | Q6: 40756 | R6: 40787 | S6: 40817 | T6: 40848 | U6: 40878 | V6: 40909 | W6: 40940 | X6: 40969 | Y6: 41000 | Z6: 41030 | AA6: 41061 | AB6: 41091 | AC6: 41122 | AD6: 41153 | AE6: 41183 | AF6: 41214 | AG6: 41244 | AH6: 41275 | AI6: 41306 | AJ6: 41334 | AK6: 41365 | AL6: 41395 | AM6: 41426 | AN6: 41456 | AO6: 41487 | AP6: 41518 | AQ6: 41548 | AR6: 41579 | AS6: 41609 | AT6: 41640 | AU6: 41671 | AV6: 41699 | AW6: 41730 | AX6: 41760 | AY6: 41791 | AZ6: 41821 | BA6: 41852 | BB6: 41883 | BC6: 41913 | BD6: 41944 | BE6: 41974 | BF6: 42005 | BG6: 42036 | BH6: 42064 | BI6: 42095 | BJ6: 42125 | BK6: 42156 | BL6: 42186 | BM6: 42217 | BN6: 42248 | BO6: 42278 | BP6: 42309 | BQ6: 42339 | BR6: 42370 | BS6: 42401 | BT6: 42430 | BU6: 42461 | BV6: 42491 | BW6: 42522 | BX6: 42552 | BY6: 42583 | BZ6: 42614 | CA6: 42644 | CB6: 42675 | CC6: 42705 | CD6: 42736 | CE6: 42767 | CF6: 42795 | CG6: 42826 | CH6: 42856 | CI6: 42887 | CJ6: 42917 | CK6: 42948 | CL6: 42979 | CM6: 43009 | CN6: 43040 | CO6: 43070 | CP6: 43101 | CQ6: 43132 | CR6: 43160 | CS6: 43191 | CT6: 43221 | CU6: 43252 | CV6: 43282 | CW6: 43313 | CX6: 43344 | CY6: 43374 | CZ6: 43405 | DA6: 43435 | DB6: 43466 | DC6: 43497 | DD6: 43525 | DE6: 43556 | DF6: 43586 | DG6: 43617 | DH6: 43647 | DI6: 43678 | DJ6: 43709 | DK6: 43739 | DL6: 43770 | DM6: 43800 | DN6: 43831 | DO6: 43862 | DP6: 43891 | DQ6: 43922 | DR6: 43952 | DS6: 43983 | DT6: 44013 | DU6: 44044 | DV6: 44075 | DW6: 44105 | DX6: 44136 | DY6: 44166 | DZ6: 44197 | EA6: 44228 | EB6: 44256 | EC6: 44287 | ED6: 44317 | EE6: 44348 | EF6: 44378 | EG6: 44409 | EH6: 44440 | EI6: 44470 | EJ6: 44501 | EK6: 44531 | EL6: 44562 | EM6: 44593 | EN6: 44621 | EO6: 44652 | EP6: 44682 | EQ6: 44713 | ER6: 44743 | ES6: 44774 | ET6: 44805 | EU6: 44835 | EV6: 44866 | EW6: 44896 | EX6: 44927 | EY6: 44958 | EZ6: 44986 | FA6: 45017 | FB6: 45047 | FC6: 45078 | FD6: 45108 | FE6: 45139 | FF6: 45170 | FG6: 45200 | FH6: 45231 | FI6: 45261 | FJ6: 45292 | FK6: 45323 | FL6: 45352 | FM6: 45383 | FN6: 45413 | FO6: 45444 | FP6: 45474 | FQ6: 45505 | FR6: 45536 | FS6: 45566 | FT6: 45597 | FU6: 45627 | FV6: 45658 | FW6: 45689 | FX6: 45717 | FY6: 45748 | FZ6: 45778 | GA6: 45809 | GB6: 45839 | GC6: 45870 | GD6: 45901 | GE6: 45931 | GF6: 45962 | GG6: 45992
B7: Month 1 estimate
B8: Month 2 estimate
B9: First Estimate | C9: =IF(ISBLANK($C$13),"N/A",$C$13) -> 70.5 | D9: =IF(ISBLANK($D$14),"N/A",$D$14) -> 70.7 | E9: =IF(ISBLANK($E$15),"N/A",$E$15) -> 70.7 | F9: =IF(ISBLANK($F$16),"N/A",$F$16) -> 70.8 | G9: =IF(ISBLANK($G$17),"N/A",$G$17) -> 70.6 | H9: =IF(ISBLANK($H$18),"N/A",$H$18) -> 70.4 | I9: =IF(ISBLANK($I$19),"N/A",$I$19) -> 70.5 | J9: =IF(ISBLANK($J$20),"N/A",$J$20) -> 70.5 | K9: =IF(ISBLANK($K$21),"N/A",$K$21) -> 70.7 | L9: =IF(ISBLANK($L$22),"N/A",$L$22) -> 70.7 | M9: =IF(ISBLANK($M$23),"N/A",$M$23) -> 70.6 | N9: =IF(ISBLANK($N$24),"N/A",$N$24) -> 70.7 | O9: =IF(ISBLANK($O$25),"N/A",$O$25) -> 70.7 | P9: =IF(ISBLANK($P$26),"N/A",$P$26) -> 70.5 | Q9: =IF(ISBLANK($Q$27),"N/A",$Q$27) -> 70.4 | R9: =IF(ISBLANK($R$28),"N/A",$R$28) -> 70.2 | S9: =IF(ISBLANK($S$29),"N/A",$S$29) -> 70.3 | T9: =IF(ISBLANK($T$30),"N/A",$T$30) -> 70.3 | U9: =IF(ISBLANK($U$31),"N/A",$U$31) -> 70.3 | V9: =IF(ISBLANK($V$32),"N/A",$V$32) -> 70.3 | W9: =IF(ISBLANK($W$33),"N/A",$W$33) -> 70.4 | X9: =IF(ISBLANK($X$34),"N/A",$X$34) -> 70.5 | Y9: =IF(ISBLANK($Y$35),"N/A",$Y$35) -> 70.6 | Z9: =IF(ISBLANK($Z$36),"N/A",$Z$36) -> 70.7 | AA9: =IF(ISBLANK($AA$37),"N/A",$AA$37) -> 71 | AB9: =IF(ISBLANK($AB$38),"N/A",$AB$38) -> 71.2 | AC9: =IF(ISBLANK($AC$39),"N/A",$AC$39) -> 71.3 | AD9: =IF(ISBLANK($AD$40),"N/A",$AD$40) -> 71.2 | AE9: =IF(ISBLANK($AE$41),"N/A",$AE$41) -> 71.2 | AF9: =IF(ISBLANK($AF$42),"N/A",$AF$42) -> 71.4 | AG9: =IF(ISBLANK($AG$43),"N/A",$AG$43) -> 71.5 | AH9: =IF(ISBLANK($AH$44),"N/A",$AH$44) -> 71.5 | AI9: =IF(ISBLANK($AI$45),"N/A",$AI$45) -> 71.4 | AJ9: =IF(ISBLANK($AJ$46),"N/A",$AJ$46) -> 71.4 | AK9: =IF(ISBLANK($AK$47),"N/A",$AK$47) -> 71.5 | AL9: =IF(ISBLANK($AL$48),"N/A",$AL$48) -> 71.4 | AM9: =IF(ISBLANK($AM$49),"N/A",$AM$49) -> 71.5 | AN9: =IF(ISBLANK($AN$50),"N/A",$AN$50) -> 71.6 | AO9: =IF(ISBLANK($AO$51),"N/A",$AO$51) -> 71.7 | AP9: =IF(ISBLANK($AP$52),"N/A",$AP$52) -> 71.8 | AQ9: =IF(ISBLANK($AQ$53),"N/A",$AQ$53) -> 72 | AR9: =IF(ISBLANK($AR$54),"N/A",$AR$54) -> 72.1 | AS9: =IF(ISBLANK($AS$55),"N/A",$AS$55) -> 72.1 | AT9: =IF(ISBLANK($AT$56),"N/A",$AT$56) -> 72.3 | AU9: =IF(ISBLANK($AU$57),"N/A",$AU$57) -> 72.6 | AV9: =IF(ISBLANK($AV$58),"N/A",$AV$58) -> 72.7 | AW9: =IF(ISBLANK($AW$59),"N/A",$AW$59) -> 72.9 | AX9: =IF(ISBLANK($AX$60),"N/A",$AX$60) -> 73.1 | AY9: =IF(ISBLANK($AY$61),"N/A",$AY$61) -> 73 | AZ9: =IF(ISBLANK($AZ$62),"N/A",$AZ$62) -> 73 | BA9: =IF(ISBLANK($BA$63),"N/A",$BA$63) -> 73 | BB9: =IF(ISBLANK($BB$64),"N/A",$BB$64) -> 73 | BC9: =IF(ISBLANK($BC$65),"N/A",$BC$65) -> 73 | BD9: =IF(ISBLANK($BD$66),"N/A",$BD$66) -> 73 | BE9: =IF(ISBLANK($BE$67),"N/A",$BE$67) -> 73.2 | BF9: =IF(ISBLANK($BF$68),"N/A",$BF$68) -> 73.3 | BG9: =IF(ISBLANK($BG$69),"N/A",$BG$69) -> 73.4 | BH9: =IF(ISBLANK($BH$70),"N/A",$BH$70) -> 73.5 | BI9: =IF(ISBLANK($BI$71),"N/A",$BI$71) -> 73.4 | BJ9: =IF(ISBLANK($BJ$72),"N/A",$BJ$72) -> 73.3 | BK9: =IF(ISBLANK($BK$73),"N/A",$BK$73) -> 73.4 | BL9: =IF(ISBLANK($BL$74),"N/A",$BL$74) -> 73.5 | BM9: =IF(ISBLANK($BM$75),"N/A",$BM$75) -> 73.6 | BN9: =IF(ISBLANK($BN$76),"N/A",$BN$76) -> 73.7 | BO9: =IF(ISBLANK($BO$77),"N/A",$BO$77) -> 73.9 | BP9: =IF(ISBLANK($BP$78),"N/A",$BP$78) -> 74 | BQ9: =IF(ISBLANK($BQ$79),"N/A",$BQ$79) -> 74.1 | BR9: =IF(ISBLANK($BR$80),"N/A",$BR$80) -> 74.1 | BS9: =IF(ISBLANK($BS$81),"N/A",$BS$81) -> 74.1 | BT9: =IF(ISBLANK($BT$82),"N/A",$BT$82) -> 74.2 | BU9: =IF(ISBLANK($BU$83),"N/A",$BU$83) -> 74.2 | BV9: =IF(ISBLANK($BV$84),"N/A",$BV$84) -> 74.4 | BW9: =IF(ISBLANK($BW$85),"N/A",$BW$85) -> 74.5 | BX9: =IF(ISBLANK($BX$86),"N/A",$BX$86) -> 74.5 | BY9: =IF(ISBLANK($BY$87),"N/A",$BY$87) -> 74.5 | BZ9: =IF(ISBLANK($BZ$88),"N/A",$BZ$88) -> 74.5 | CA9: =IF(ISBLANK($CA$89),"N/A",$CA$89) -> 74.4 | CB9: =IF(ISBLANK($CB$90),"N/A",$CB$90) -> 74.5 | CC9: =IF(ISBLANK($CC$91),"N/A",$CC$91) -> 74.6 | CD9: =IF(ISBLANK($CD$92),"N/A",$CD$92) -> 74.6 | CE9: =IF(ISBLANK($CE$93),"N/A",$CE$93) -> 74.6 | CF9: =IF(ISBLANK($CF$94),"N/A",$CF$94) -> 74.8 | CG9: =IF(ISBLANK($CG$95),"N/A",$CG$95) -> 74.8 | CH9: =IF(ISBLANK($CH$96),"N/A",$CH$96) -> 74.9 | CI9: =IF(ISBLANK($CI$97),"N/A",$CI$97) -> 75.1 | CJ9: =IF(ISBLANK($CJ$98),"N/A",$CJ$98) -> 75.3 | CK9: =IF(ISBLANK($CK$99),"N/A",$CK$99) -> 75.1 | CL9: =IF(ISBLANK($CL$100),"N/A",$CL$100) -> 75 | CM9: =IF(ISBLANK($CM$101),"N/A",$CM$101) -> 75.1 | CN9: =IF(ISBLANK($CN$102),"N/A",$CN$102) -> 75.3 | CO9: =IF(ISBLANK($CO$103),"N/A",$CO$103) -> 75.2 | CP9: =IF(ISBLANK($CP$104),"N/A",$CP$104) -> 75.3 | CQ9: =IF(ISBLANK($CQ$105),"N/A",$CQ$105) -> 75.4 | CR9: =IF(ISBLANK($CR$106),"N/A",$CR$106) -> 75.6 | CS9: =IF(ISBLANK($CS$107),"N/A",$CS$107) -> 75.6 | CT9: =IF(ISBLANK($CT$108),"N/A",$CT$108) -> 75.7 | CU9: =IF(ISBLANK($CU$109),"N/A",$CU$109) -> 75.6 | CV9: =IF(ISBLANK($CV$110),"N/A",$CV$110) -> 75.5 | CW9: =IF(ISBLANK($CW$111),"N/A",$CW$111) -> 75.5 | CX9: =IF(ISBLANK($CX$112),"N/A",$CX$112) -> 75.5 | CY9: =IF(ISBLANK($CY$113),"N/A",$CY$113) -> 75.7 | CZ9: =IF(ISBLANK($CZ$114),"N/A",$CZ$114) -> 75.8 | DA9: =IF(ISBLANK($DA$115),"N/A",$DA$115) -> 75.8 | DB9: =IF(ISBLANK($DB$116),"N/A",$DB$116) -> 76.1 | DC9: =IF(ISBLANK($DC$117),"N/A",$DC$117) -> 76.1 | DD9: =IF(ISBLANK($DD$118),"N/A",$DD$118) -> 76.1 | DE9: =IF(ISBLANK($DE$119),"N/A",$DE$119) -> 76.1 | DF9: =IF(ISBLANK($DF$120),"N/A",$DF$120) -> 76 | DG9: =IF(ISBLANK($DG$121),"N/A",$DG$121) -> 76.1 | DH9: =IF(ISBLANK($DH$122),"N/A",$DH$122) -> 76.1 | DI9: =IF(ISBLANK($DI$123),"N/A",$DI$123) -> 75.9 | DJ9: =IF(ISBLANK($DJ$124),"N/A",$DJ$124) -> 76 | DK9: =IF(ISBLANK($DK$125),"N/A",$DK$125) -> 76.2 | DL9: =IF(ISBLANK($DL$126),"N/A",$DL$126) -> 76.3 | DM9: =IF(ISBLANK($DM$127),"N/A",$DM$127) -> 76.5 | DN9: =IF(ISBLANK($DN$128),"N/A",$DN$128) -> 76.5 | DO9: =IF(ISBLANK($DO$129),"N/A",$DO$129) -> 76.6 | DP9: =IF(ISBLANK($DP$130),"N/A",$DP$130) -> 76.6 | DQ9: =IF(ISBLANK($DQ$131),"N/A",$DQ$131) -> 76.4 | DR9: =IF(ISBLANK($DR$132),"N/A",$DR$132) -> 76.4 | DS9: =IF(ISBLANK($DS$133),"N/A",$DS$133) -> 76.4 | DT9: =IF(ISBLANK($DT$134),"N/A",$DT$134) -> 76.5 | DU9: =IF(ISBLANK($DU$135),"N/A",$DU$135) -> 75.56054 | DV9: =IF(ISBLANK($DV$136),"N/A",$DV$136) -> 75.3 | DW9: =IF(ISBLANK($DW$137),"N/A",$DW$137) -> 75.2 | DX9: =IF(ISBLANK($DX$138),"N/A",$DX$138) -> 75.2 | DY9: =IF(ISBLANK($DY$139),"N/A",$DY$139) -> 75 | DZ9: =IF(ISBLANK($DZ$140),"N/A",$DZ$140) -> 75 | EA9: =IF(ISBLANK($EA$141),"N/A",$EA$141) -> 75.1 | EB9: =IF(ISBLANK($EB$142),"N/A",$EB$142) -> 75.2 | EC9: =IF(ISBLANK($EC$143),"N/A",$EC$143) -> 75.2 | ED9: =IF(ISBLANK($ED$144),"N/A",$ED$144) -> 74.804889 | EE9: =IF(ISBLANK($EE$145),"N/A",$EE$145) -> 75.072313 | EF9: =IF(ISBLANK($EF$146),"N/A",$EF$146) -> 75.221203 | EG9: =IF(ISBLANK($EG$147),"N/A",$EG$147) -> 75.304371 | EH9: =IF(ISBLANK($EH$148),"N/A",$EH$148) -> 75.426779 | EI9: =IF(ISBLANK($EI$149),"N/A",$EI$149) -> 75.461812 | EJ9: =IF(ISBLANK($EJ$150),"N/A",$EJ$150) -> 75.5 | EK9: =IF(ISBLANK($EK$151),"N/A",$EK$151) -> 75.5 | EL9: =IF(ISBLANK($EL$152),"N/A",$EL$152) -> 75.6 | EM9: =IF(ISBLANK($EM$153),"N/A",$EM$153) -> 75.485512 | EN9: =IF(ISBLANK($EN$154),"N/A",$EN$154) -> 75.658527 | EO9: =IF(ISBLANK($EO$155),"N/A",$EO$155) -> 75.648993 | EP9: =IF(ISBLANK($EP$156),"N/A",$EP$156) -> 75.866475 | EQ9: =IF(ISBLANK($EQ$157),"N/A",$EQ$157) -> 75.518216 | ER9: =IF(ISBLANK($ER$158),"N/A",$ER$158) -> 75.4242 | ES9: =IF(ISBLANK($ES$159),"N/A",$ES$159) -> 75.5 | ET9: =IF(ISBLANK($ET$160),"N/A",$ET$160) -> 75.5 | EU9: =IF(ISBLANK($EU$161),"N/A",$EU$161) -> 75.590937 | EV9: =IF(ISBLANK($EV$162),"N/A",$EV$162) -> 75.6 | EW9: =IF(ISBLANK($EW$163),"N/A",$EW$163) -> 75.630705 | EX9: =IF(ISBLANK($EX$164),"N/A",$EX$164) -> 75.729704 | EY9: =IF(ISBLANK($EY$165),"N/A",$EY$165) -> 75.809139 | EZ9: =IF(ISBLANK($EZ$166),"N/A",$EZ$166) -> 75.876896 | FA9: =IF(ISBLANK($FA$167),"N/A",$FA$167) -> 75.97215 | FB9: =IF(ISBLANK($FB$168),"N/A",$FB$168) -> 75.973187 | FC9: =IF(ISBLANK($FC$169),"N/A",$FC$169) -> 75.729763 | FD9: =IF(ISBLANK($FD$170),"N/A",$FD$170) -> 75.483668 | FE9: =IF(ISBLANK($FE$171),"N/A",$FE$171) -> 75.270661 | FF9: =IF(ISBLANK($FF$172),"N/A",$FF$172) -> 75.443652 | FG9: =IF(ISBLANK($FG$173),"N/A",$FG$173) -> 75.571136 | FH9: =IF(ISBLANK($FH$174),"N/A",$FH$174) -> 75.68751 | FI9: =IF(ISBLANK($FI$175),"N/A",$FI$175) -> 75.008565 | FJ9: =IF(ISBLANK($FJ$176),"N/A",$FJ$176) -> 74.998781 | FK9: =IF(ISBLANK($FK$177),"N/A",$FK$177) -> 74.487887 | FL9: =IF(ISBLANK($FL$178),"N/A",$FL$178) -> 74.451316 | FM9: =IF(ISBLANK($FM$179),"N/A",$FM$179) -> 74.298008 | FN9: =IF(ISBLANK($FN$180),"N/A",$FN$180) -> 74.361419 | FO9: =IF(ISBLANK($FO$181),"N/A",$FO$181) -> 74.517672 | FP9: =IF(ISBLANK($FP$182),"N/A",$FP$182) -> 74.785861 | FQ9: =IF(ISBLANK($FQ$183),"N/A",$FQ$183) -> 75.005738 | FR9: =IF(ISBLANK($FR$184),"N/A",$FR$184) -> 74.811055 | FS9: =IF(ISBLANK($FS$185),"N/A",$FS$185) -> 74.889153 | FT9: =IF(ISBLANK($FT$186),"N/A",$FT$186) -> 74.841084 | FU9: =IF(ISBLANK($FU$187),"N/A",$FU$187) -> 74.938223 | FV9: =IF(ISBLANK($FV$188),"N/A",$FV$188) -> 75.006018 | FW9: =IF(ISBLANK($FW$189),"N/A",$FW$189) -> 75.06605 | FX9: =IF(ISBLANK($FX$190),"N/A",$FX$190) -> 74.999445 | FY9: =IF(ISBLANK($FY$191),"N/A",$FY$191) -> 75.057705 | FZ9: =IF(ISBLANK($FZ$192),"N/A",$FZ$192) -> 75.241221 | GA9: =IF(ISBLANK($GA$193),"N/A",$GA$193) -> 75.268461 | GB9: =IF(ISBLANK($GB$194),"N/A",$GB$194) -> 75.174093 | GC9: =IF(ISBLANK($GC$195),"N/A",$GC$195) -> 75.063593 | GD9: =IF(ISBLANK($GD$196),"N/A",$GD$196) -> 75.041595 | GE9: =IF(ISBLANK($GE$197),"N/A",$GE$197) -> 74.915831 | GF9: =IF(ISBLANK($GF$198),"N/A",$GF$198) -> 75.092992 | GG9: =IF(ISBLANK($GG$199),"N/A",$GG$199) -> 74.959733
B10: Value 12 Months later | C10: =IF(ISBLANK($C$25),"N/A",$C$25) -> 70.5 | D10: =IF(ISBLANK($D$26),"N/A",$D$26) -> 70.7 | E10: =IF(ISBLANK($E$27),"N/A",$E$27) -> 70.7 | F10: =IF(ISBLANK($F$28),"N/A",$F$28) -> 70.8 | G10: =IF(ISBLANK($G$29),"N/A",$G$29) -> 70.6 | H10: =IF(ISBLANK($H$30),"N/A",$H$30) -> 70.4 | I10: =IF(ISBLANK($I$31),"N/A",$I$31) -> 70.5 | J10: =IF(ISBLANK($J$32),"N/A",$J$32) -> 70.5 | K10: =IF(ISBLANK($K$33),"N/A",$K$33) -> 70.7 | L10: =IF(ISBLANK($L$34),"N/A",$L$34) -> 70.7 | M10: =IF(ISBLANK($M$35),"N/A",$M$35) -> 70.6 | N10: =IF(ISBLANK($N$36),"N/A",$N$36) -> 70.7 | O10: =IF(ISBLANK($O$37),"N/A",$O$37) -> 70.6 | P10: =IF(ISBLANK($P$38),"N/A",$P$38) -> 70.4 | Q10: =IF(ISBLANK($Q$39),"N/A",$Q$39) -> 70.3 | R10: =IF(ISBLANK($R$40),"N/A",$R$40) -> 70.2 | S10: =IF(ISBLANK($S$41),"N/A",$S$41) -> 70.3 | T10: =IF(ISBLANK($T$42),"N/A",$T$42) -> 70.3 | U10: =IF(ISBLANK($U$43),"N/A",$U$43) -> 70.4 | V10: =IF(ISBLANK($V$44),"N/A",$V$44) -> 70.4 | W10: =IF(ISBLANK($W$45),"N/A",$W$45) -> 70.5 | X10: =IF(ISBLANK($X$46),"N/A",$X$46) -> 70.6 | Y10: =IF(ISBLANK($Y$47),"N/A",$Y$47) -> 70.7 | Z10: =IF(ISBLANK($Z$48),"N/A",$Z$48) -> 70.8 | AA10: =IF(ISBLANK($AA$49),"N/A",$AA$49) -> 71 | AB10: =IF(ISBLANK($AB$50),"N/A",$AB$50) -> 71.2 | AC10: =IF(ISBLANK($AC$51),"N/A",$AC$51) -> 71.3 | AD10: =IF(ISBLANK($AD$52),"N/A",$AD$52) -> 71.2 | AE10: =IF(ISBLANK($AE$53),"N/A",$AE$53) -> 71.2 | AF10: =IF(ISBLANK($AF$54),"N/A",$AF$54) -> 71.5 | AG10: =IF(ISBLANK($AG$55),"N/A",$AG$55) -> 71.6 | AH10: =IF(ISBLANK($AH$56),"N/A",$AH$56) -> 71.5 | AI10: =IF(ISBLANK($AI$57),"N/A",$AI$57) -> 71.4 | AJ10: =IF(ISBLANK($AJ$58),"N/A",$AJ$58) -> 71.4 | AK10: =IF(ISBLANK($AK$59),"N/A",$AK$59) -> 71.5 | AL10: =IF(ISBLANK($AL$60),"N/A",$AL$60) -> 71.4 | AM10: =IF(ISBLANK($AM$61),"N/A",$AM$61) -> 71.5 | AN10: =IF(ISBLANK($AN$62),"N/A",$AN$62) -> 71.6 | AO10: =IF(ISBLANK($AO$63),"N/A",$AO$63) -> 71.5 | AP10: =IF(ISBLANK($AP$64),"N/A",$AP$64) -> 71.6 | AQ10: =IF(ISBLANK($AQ$65),"N/A",$AQ$65) -> 71.8 | AR10: =IF(ISBLANK($AR$66),"N/A",$AR$66) -> 72 | AS10: =IF(ISBLANK($AS$67),"N/A",$AS$67) -> 72 | AT10: =IF(ISBLANK($AT$68),"N/A",$AT$68) -> 72.1 | AU10: =IF(ISBLANK($AU$69),"N/A",$AU$69) -> 72.4 | AV10: =IF(ISBLANK($AV$70),"N/A",$AV$70) -> 72.5 | AW10: =IF(ISBLANK($AW$71),"N/A",$AW$71) -> 72.7 | AX10: =IF(ISBLANK($AX$72),"N/A",$AX$72) -> 72.9 | AY10: =IF(ISBLANK($AY$73),"N/A",$AY$73) -> 72.8 | AZ10: =IF(ISBLANK($AZ$74),"N/A",$AZ$74) -> 72.8 | BA10: =IF(ISBLANK($BA$75),"N/A",$BA$75) -> 73 | BB10: =IF(ISBLANK($BB$76),"N/A",$BB$76) -> 73 | BC10: =IF(ISBLANK($BC$77),"N/A",$BC$77) -> 73 | BD10: =IF(ISBLANK($BD$78),"N/A",$BD$78) -> 73 | BE10: =IF(ISBLANK($BE$79),"N/A",$BE$79) -> 73.2 | BF10: =IF(ISBLANK($BF$80),"N/A",$BF$80) -> 73.3 | BG10: =IF(ISBLANK($BG$81),"N/A",$BG$81) -> 73.4 | BH10: =IF(ISBLANK($BH$82),"N/A",$BH$82) -> 73.5 | BI10: =IF(ISBLANK($BI$83),"N/A",$BI$83) -> 73.4 | BJ10: =IF(ISBLANK($BJ$84),"N/A",$BJ$84) -> 73.4 | BK10: =IF(ISBLANK($BK$85),"N/A",$BK$85) -> 73.4 | BL10: =IF(ISBLANK($BL$86),"N/A",$BL$86) -> 73.5 | BM10: =IF(ISBLANK($BM$87),"N/A",$BM$87) -> 73.6 | BN10: =IF(ISBLANK($BN$88),"N/A",$BN$88) -> 73.8 | BO10: =IF(ISBLANK($BO$89),"N/A",$BO$89) -> 73.9 | BP10: =IF(ISBLANK($BP$90),"N/A",$BP$90) -> 74 | BQ10: =IF(ISBLANK($BQ$91),"N/A",$BQ$91) -> 74.1 | BR10: =IF(ISBLANK($BR$92),"N/A",$BR$92) -> 74.1 | BS10: =IF(ISBLANK($BS$93),"N/A",$BS$93) -> 74.1 | BT10: =IF(ISBLANK($BT$94),"N/A",$BT$94) -> 74.2 | BU10: =IF(ISBLANK($BU$95),"N/A",$BU$95) -> 74.2 | BV10: =IF(ISBLANK($BV$96),"N/A",$BV$96) -> 74.4 | BW10: =IF(ISBLANK($BW$97),"N/A",$BW$97) -> 74.4 | BX10: =IF(ISBLANK($BX$98),"N/A",$BX$98) -> 74.5 | BY10: =IF(ISBLANK($BY$99),"N/A",$BY$99) -> 74.5 | BZ10: =IF(ISBLANK($BZ$100),"N/A",$BZ$100) -> 74.4 | CA10: =IF(ISBLANK($CA$101),"N/A",$CA$101) -> 74.4 | CB10: =IF(ISBLANK($CB$102),"N/A",$CB$102) -> 74.5 | CC10: =IF(ISBLANK($CC$103),"N/A",$CC$103) -> 74.6 | CD10: =IF(ISBLANK($CD$104),"N/A",$CD$104) -> 74.6 | CE10: =IF(ISBLANK($CE$105),"N/A",$CE$105) -> 74.6 | CF10: =IF(ISBLANK($CF$106),"N/A",$CF$106) -> 74.8 | CG10: =IF(ISBLANK($CG$107),"N/A",$CG$107) -> 74.8 | CH10: =IF(ISBLANK($CH$108),"N/A",$CH$108) -> 74.9 | CI10: =IF(ISBLANK($CI$109),"N/A",$CI$109) -> 75.1 | CJ10: =IF(ISBLANK($CJ$110),"N/A",$CJ$110) -> 75.3 | CK10: =IF(ISBLANK($CK$111),"N/A",$CK$111) -> 75.1 | CL10: =IF(ISBLANK($CL$112),"N/A",$CL$112) -> 75 | CM10: =IF(ISBLANK($CM$113),"N/A",$CM$113) -> 75.1 | CN10: =IF(ISBLANK($CN$114),"N/A",$CN$114) -> 75.3 | CO10: =IF(ISBLANK($CO$115),"N/A",$CO$115) -> 75.2 | CP10: =IF(ISBLANK($CP$116),"N/A",$CP$116) -> 75.3 | CQ10: =IF(ISBLANK($CQ$117),"N/A",$CQ$117) -> 75.4 | CR10: =IF(ISBLANK($CR$118),"N/A",$CR$118) -> 75.6 | CS10: =IF(ISBLANK($CS$119),"N/A",$CS$119) -> 75.6 | CT10: =IF(ISBLANK($CT$120),"N/A",$CT$120) -> 75.6 | CU10: =IF(ISBLANK($CU$121),"N/A",$CU$121) -> 75.5 | CV10: =IF(ISBLANK($CV$122),"N/A",$CV$122) -> 75.5 | CW10: =IF(ISBLANK($CW$123),"N/A",$CW$123) -> 75.6 | CX10: =IF(ISBLANK($CX$124),"N/A",$CX$124) -> 75.6 | CY10: =IF(ISBLANK($CY$125),"N/A",$CY$125) -> 75.7 | CZ10: =IF(ISBLANK($CZ$126),"N/A",$CZ$126) -> 75.8 | DA10: =IF(ISBLANK($DA$127),"N/A",$DA$127) -> 75.8 | DB10: =IF(ISBLANK($DB$128),"N/A",$DB$128) -> 76.1 | DC10: =IF(ISBLANK($DC$129),"N/A",$DC$129) -> 76.1 | DD10: =IF(ISBLANK($DD$130),"N/A",$DD$130) -> 76.1 | DE10: =IF(ISBLANK($DE$131),"N/A",$DE$131) -> 76.1 | DF10: =IF(ISBLANK($DF$132),"N/A",$DF$132) -> 75.8 | DG10: =IF(ISBLANK($DG$133),"N/A",$DG$133) -> 76.1 | DH10: =IF(ISBLANK($DH$134),"N/A",$DH$134) -> 76 | DI10: =IF(ISBLANK($DI$135),"N/A",$DI$135) -> 75.9 | DJ10: =IF(ISBLANK($DJ$136),"N/A",$DJ$136) -> 76 | DK10: =IF(ISBLANK($DK$137),"N/A",$DK$137) -> 76.2 | DL10: =IF(ISBLANK($DL$138),"N/A",$DL$138) -> 76.3 | DM10: =IF(ISBLANK($DM$139),"N/A",$DM$139) -> 76.5 | DN10: =IF(ISBLANK($DN$140),"N/A",$DN$140) -> 76.5 | DO10: =IF(ISBLANK($DO$141),"N/A",$DO$141) -> 76.6 | DP10: =IF(ISBLANK($DP$142),"N/A",$DP$142) -> 76.340152 | DQ10: =IF(ISBLANK($DQ$143),"N/A",$DQ$143) -> 76.023623 | DR10: =IF(ISBLANK($DR$144),"N/A",$DR$144) -> 75.8418 | DS10: =IF(ISBLANK($DS$145),"N/A",$DS$145) -> 75.748395 | DT10: =IF(ISBLANK($DT$146),"N/A",$DT$146) -> 75.62516 | DU10: =IF(ISBLANK($DU$147),"N/A",$DU$147) -> 75.370426 | DV10: =IF(ISBLANK($DV$148),"N/A",$DV$148) -> 75.032894 | DW10: =IF(ISBLANK($DW$149),"N/A",$DW$149) -> 74.935644 | DX10: =IF(ISBLANK($DX$150),"N/A",$DX$150) -> 74.948703 | DY10: =IF(ISBLANK($DY$151),"N/A",$DY$151) -> 74.6539 | DZ10: =IF(ISBLANK($DZ$152),"N/A",$DZ$152) -> 74.61004 | EA10: =IF(ISBLANK($EA$153),"N/A",$EA$153) -> 74.720603 | EB10: =IF(ISBLANK($EB$154),"N/A",$EB$154) -> 74.724823 | EC10: =IF(ISBLANK($EC$155),"N/A",$EC$155) -> 74.692215 | ED10: =IF(ISBLANK($ED$156),"N/A",$ED$156) -> 74.750852 | EE10: =IF(ISBLANK($EE$157),"N/A",$EE$157) -> 75.019872 | EF10: =IF(ISBLANK($EF$158),"N/A",$EF$158) -> 75.142336 | EG10: =IF(ISBLANK($EG$159),"N/A",$EG$159) -> 75.242012 | EH10: =IF(ISBLANK($EH$160),"N/A",$EH$160) -> 75.336738 | EI10: =IF(ISBLANK($EI$161),"N/A",$EI$161) -> 75.385208 | EJ10: =IF(ISBLANK($EJ$162),"N/A",$EJ$162) -> 75.417537 | EK10: =IF(ISBLANK($EK$163),"N/A",$EK$163) -> 75.469459 | EL10: =IF(ISBLANK($EL$164),"N/A",$EL$164) -> 75.431988 | EM10: =IF(ISBLANK($EM$165),"N/A",$EM$165) -> 75.465306 | EN10: =IF(ISBLANK($EN$166),"N/A",$EN$166) -> 75.626684 | EO10: =IF(ISBLANK($EO$167),"N/A",$EO$167) -> 75.648993 | EP10: =IF(ISBLANK($EP$168),"N/A",$EP$168) -> 75.866475 | EQ10: =IF(ISBLANK($EQ$169),"N/A",$EQ$169) -> 75.518216 | ER10: =IF(ISBLANK($ER$170),"N/A",$ER$170) -> 75.4242 | ES10: =IF(ISBLANK($ES$171),"N/A",$ES$171) -> 75.5 | ET10: =IF(ISBLANK($ET$172),"N/A",$ET$172) -> 75.5 | EU10: =IF(ISBLANK($EU$173),"N/A",$EU$173) -> 75.590937 | EV10: =IF(ISBLANK($EV$174),"N/A",$EV$174) -> 75.6 | EW10: =IF(ISBLANK($EW$175),"N/A",$EW$175) -> 75.18609 | EX10: =IF(ISBLANK($EX$176),"N/A",$EX$176) -> 75.243637 | EY10: =IF(ISBLANK($EY$177),"N/A",$EY$177) -> 75.238481 | EZ10: =IF(ISBLANK($EZ$178),"N/A",$EZ$178) -> 75.278703 | FA10: =IF(ISBLANK($FA$179),"N/A",$FA$179) -> 75.43069 | FB10: =IF(ISBLANK($FB$180),"N/A",$FB$180) -> 75.460293 | FC10: =IF(ISBLANK($FC$181),"N/A",$FC$181) -> 75.169188 | FD10: =IF(ISBLANK($FD$182),"N/A",$FD$182) -> 74.911923 | FE10: =IF(ISBLANK($FE$183),"N/A",$FE$183) -> 74.744985 | FF10: =IF(ISBLANK($FF$184),"N/A",$FF$184) -> 74.846469 | FG10: =IF(ISBLANK($FG$185),"N/A",$FG$185) -> 74.869395 | FH10: =IF(ISBLANK($FH$186),"N/A",$FH$186) -> 74.856164 | FI10: =IF(ISBLANK($FI$187),"N/A",$FI$187) -> 74.84999 | FJ10: =IF(ISBLANK($FJ$188),"N/A",$FJ$188) -> 74.659177 | FK10: =IF(ISBLANK($FK$189),"N/A",$FK$189) -> 74.559012 | FL10: =IF(ISBLANK($FL$190),"N/A",$FL$190) -> 74.495675 | FM10: =IF(ISBLANK($FM$191),"N/A",$FM$191) -> 74.396209 | FN10: =IF(ISBLANK($FN$192),"N/A",$FN$192) -> 74.407764 | FO10: =IF(ISBLANK($FO$193),"N/A",$FO$193) -> 74.574397 | FP10: =IF(ISBLANK($FP$194),"N/A",$FP$194) -> 74.722903 | FQ10: =IF(ISBLANK($FQ$195),"N/A",$FQ$195) -> 74.985704 | FR10: =IF(ISBLANK($FR$196),"N/A",$FR$196) -> 74.937976 | FS10: =IF(ISBLANK($FS$197),"N/A",$FS$197) -> 74.902473 | FT10: =IF(ISBLANK($FT$198),"N/A",$FT$198) -> 74.850935 | FU10: =IF(ISBLANK($FU$199),"N/A",$FU$199) -> 74.956007 | FV10: N/A | FW10: =IF(ISBLANK($FW$201),"N/A",$FW$201) -> N/A | FX10: =IF(ISBLANK($FX$202),"N/A",$FX$202) -> N/A | FY10: =IF(ISBLANK($FY$203),"N/A",$FY$203) -> N/A | FZ10: =IF(ISBLANK($FZ$204),"N/A",$FZ$204) -> N/A | GA10: =IF(ISBLANK($GA$205),"N/A",$GA$205) -> N/A | GB10: =IF(ISBLANK($GB$206),"N/A",$GB$206) -> N/A | GC10: =IF(ISBLANK($GC$207),"N/A",$GC$207) -> N/A | GD10: =IF(ISBLANK($GD$208),"N/A",$GD$208) -> N/A | GE10: =IF(ISBLANK($GE$209),"N/A",$GE$209) -> N/A | GF10: =IF(ISBLANK($GF$210),"N/A",$GF$210) -> N/A | GG10: =IF(ISBLANK($GG$211),"N/A",$GG$211) -> N/A
B11: BB1 Estimate
B12: BB2 Estimate
B13: 40391 | C13: 70.5
B14: 40422 | C14: 70.5 | D14: 70.7
B15: 40452 | C15: 70.5 | D15: 70.7 | E15: 70.7
B16: 40483 | C16: 70.5 | D16: 70.7 | E16: 70.7 | F16: 70.8
B17: 40513 | C17: 70.5 | D17: 70.7 | E17: 70.7 | F17: 70.8 | G17: 70.6
B18: 40544 | C18: 70.5 | D18: 70.7 | E18: 70.7 | F18: 70.8 | G18: 70.6 | H18: 70.4
B19: 40575 | C19: 70.5 | D19: 70.7 | E19: 70.7 | F19: 70.8 | G19: 70.6 | H19: 70.4 | I19: 70.5
B20: 40603 | C20: 70.5 | D20: 70.7 | E20: 70.7 | F20: 70.8 | G20: 70.6 | H20: 70.4 | I20: 70.5 | J20: 70.5
B21: 40634 | C21: 70.5 | D21: 70.7 | E21: 70.7 | F21: 70.8 | G21: 70.6 | H21: 70.4 | I21: 70.5 | J21: 70.5 | K21: 70.7
B22: 40664 | C22: 70.5 | D22: 70.7 | E22: 70.7 | F22: 70.8 | G22: 70.6 | H22: 70.4 | I22: 70.5 | J22: 70.5 | K22: 70.7 | L22: 70.7
B23: 40695 | C23: 70.5 | D23: 70.7 | E23: 70.7 | F23: 70.8 | G23: 70.6 | H23: 70.4 | I23: 70.5 | J23: 70.5 | K23: 70.7 | L23: 70.7 | M23: 70.6
B24: 40725 | C24: 70.5 | D24: 70.7 | E24: 70.7 | F24: 70.8 | G24: 70.6 | H24: 70.4 | I24: 70.5 | J24: 70.5 | K24: 70.7 | L24: 70.7 | M24: 70.6 | N24: 70.7
B25: 40756 | C25: 70.5 | D25: 70.7 | E25: 70.7 | F25: 70.8 | G25: 70.6 | H25: 70.4 | I25: 70.5 | J25: 70.5 | K25: 70.7 | L25: 70.7 | M25: 70.6 | N25: 70.7 | O25: 70.7
B26: 40787 | C26: 70.5 | D26: 70.7 | E26: 70.7 | F26: 70.8 | G26: 70.6 | H26: 70.4 | I26: 70.5 | J26: 70.5 | K26: 70.7 | L26: 70.7 | M26: 70.6 | N26: 70.7 | O26: 70.7 | P26: 70.5
B27: 40817 | C27: 70.5 | D27: 70.7 | E27: 70.7 | F27: 70.8 | G27: 70.6 | H27: 70.4 | I27: 70.5 | J27: 70.5 | K27: 70.7 | L27: 70.7 | M27: 70.6 | N27: 70.7 | O27: 70.7 | P27: 70.5 | Q27: 70.4
B28: 40848 | C28: 70.5 | D28: 70.7 | E28: 70.7 | F28: 70.8 | G28: 70.6 | H28: 70.4 | I28: 70.5 | J28: 70.5 | K28: 70.7 | L28: 70.7 | M28: 70.6 | N28: 70.7 | O28: 70.7 | P28: 70.5 | Q28: 70.4 | R28: 70.2
B29: 40878 | C29: 70.5 | D29: 70.7 | E29: 70.7 | F29: 70.8 | G29: 70.6 | H29: 70.4 | I29: 70.5 | J29: 70.5 | K29: 70.7 | L29: 70.7 | M29: 70.6 | N29: 70.7 | O29: 70.7 | P29: 70.5 | Q29: 70.4 | R29: 70.2 | S29: 70.3
B30: 40909 | C30: 70.5 | D30: 70.7 | E30: 70.7 | F30: 70.8 | G30: 70.6 | H30: 70.4 | I30: 70.5 | J30: 70.5 | K30: 70.7 | L30: 70.7 | M30: 70.6 | N30: 70.7 | O30: 70.7 | P30: 70.5 | Q30: 70.4 | R30: 70.2 | S30: 70.3 | T30: 70.3
B31: 40940 | C31: 70.5 | D31: 70.7 | E31: 70.7 | F31: 70.8 | G31: 70.6 | H31: 70.4 | I31: 70.5 | J31: 70.5 | K31: 70.7 | L31: 70.7 | M31: 70.6 | N31: 70.7 | O31: 70.7 | P31: 70.5 | Q31: 70.4 | R31: 70.2 | S31: 70.3 | T31: 70.3 | U31: 70.3
B32: 40969 | C32: 70.5 | D32: 70.7 | E32: 70.7 | F32: 70.8 | G32: 70.6 | H32: 70.4 | I32: 70.5 | J32: 70.5 | K32: 70.7 | L32: 70.7 | M32: 70.6 | N32: 70.7 | O32: 70.7 | P32: 70.5 | Q32: 70.4 | R32: 70.2 | S32: 70.3 | T32: 70.3 | U32: 70.3 | V32: 70.3
B33: 41000 | C33: 70.5 | D33: 70.7 | E33: 70.7 | F33: 70.8 | G33: 70.6 | H33: 70.4 | I33: 70.5 | J33: 70.5 | K33: 70.7 | L33: 70.7 | M33: 70.6 | N33: 70.7 | O33: 70.7 | P33: 70.5 | Q33: 70.4 | R33: 70.2 | S33: 70.3 | T33: 70.3 | U33: 70.3 | V33: 70.3 | W33: 70.4
B34: 41030 | C34: 70.5 | D34: 70.7 | E34: 70.7 | F34: 70.8 | G34: 70.6 | H34: 70.4 | I34: 70.5 | J34: 70.5 | K34: 70.7 | L34: 70.7 | M34: 70.6 | N34: 70.7 | O34: 70.7 | P34: 70.5 | Q34: 70.4 | R34: 70.2 | S34: 70.3 | T34: 70.3 | U34: 70.3 | V34: 70.3 | W34: 70.4 | X34: 70.5
B35: 41061 | C35: 70.5 | D35: 70.7 | E35: 70.7 | F35: 70.8 | G35: 70.6 | H35: 70.4 | I35: 70.5 | J35: 70.5 | K35: 70.7 | L35: 70.7 | M35: 70.6 | N35: 70.7 | O35: 70.7 | P35: 70.5 | Q35: 70.4 | R35: 70.2 | S35: 70.3 | T35: 70.3 | U35: 70.3 | V35: 70.3 | W35: 70.4 | X35: 70.5 | Y35: 70.6
B36: 41091 | C36: 70.5 | D36: 70.7 | E36: 70.7 | F36: 70.8 | G36: 70.6 | H36: 70.4 | I36: 70.5 | J36: 70.5 | K36: 70.7 | L36: 70.7 | M36: 70.6 | N36: 70.7 | O36: 70.7 | P36: 70.5 | Q36: 70.4 | R36: 70.2 | S36: 70.3 | T36: 70.3 | U36: 70.3 | V36: 70.3 | W36: 70.4 | X36: 70.5 | Y36: 70.6 | Z36: 70.7
B37: 41122 | C37: 70.4 | D37: 70.7 | E37: 70.7 | F37: 70.8 | G37: 70.6 | H37: 70.5 | I37: 70.5 | J37: 70.6 | K37: 70.7 | L37: 70.7 | M37: 70.6 | N37: 70.7 | O37: 70.6 | P37: 70.4 | Q37: 70.3 | R37: 70.2 | S37: 70.3 | T37: 70.3 | U37: 70.4 | V37: 70.4 | W37: 70.5 | X37: 70.6 | Y37: 70.7 | Z37: 70.8 | AA37: 71
B38: 41153 | C38: 70.4 | D38: 70.7 | E38: 70.7 | F38: 70.8 | G38: 70.6 | H38: 70.5 | I38: 70.5 | J38: 70.6 | K38: 70.7 | L38: 70.7 | M38: 70.6 | N38: 70.7 | O38: 70.6 | P38: 70.4 | Q38: 70.3 | R38: 70.2 | S38: 70.3 | T38: 70.3 | U38: 70.4 | V38: 70.4 | W38: 70.5 | X38: 70.6 | Y38: 70.7 | Z38: 70.8 | AA38: 71 | AB38: 71.2
B39: 41183 | C39: 70.4 | D39: 70.7 | E39: 70.7 | F39: 70.8 | G39: 70.6 | H39: 70.5 | I39: 70.5 | J39: 70.6 | K39: 70.7 | L39: 70.7 | M39: 70.6 | N39: 70.7 | O39: 70.6 | P39: 70.4 | Q39: 70.3 | R39: 70.2 | S39: 70.3 | T39: 70.3 | U39: 70.4 | V39: 70.4 | W39: 70.5 | X39: 70.6 | Y39: 70.7 | Z39: 70.8 | AA39: 71 | AB39: 71.2 | AC39: 71.3
B40: 41214 | C40: 70.4 | D40: 70.7 | E40: 70.7 | F40: 70.8 | G40: 70.6 | H40: 70.5 | I40: 70.5 | J40: 70.6 | K40: 70.7 | L40: 70.7 | M40: 70.6 | N40: 70.7 | O40: 70.6 | P40: 70.4 | Q40: 70.3 | R40: 70.2 | S40: 70.3 | T40: 70.3 | U40: 70.4 | V40: 70.4 | W40: 70.5 | X40: 70.6 | Y40: 70.7 | Z40: 70.8 | AA40: 71 | AB40: 71.2 | AC40: 71.3 | AD40: 71.2
B41: 41244 | C41: 70.4 | D41: 70.7 | E41: 70.7 | F41: 70.8 | G41: 70.6 | H41: 70.5 | I41: 70.5 | J41: 70.6 | K41: 70.7 | L41: 70.7 | M41: 70.6 | N41: 70.7 | O41: 70.6 | P41: 70.4 | Q41: 70.3 | R41: 70.2 | S41: 70.3 | T41: 70.3 | U41: 70.4 | V41: 70.4 | W41: 70.5 | X41: 70.6 | Y41: 70.7 | Z41: 70.8 | AA41: 71 | AB41: 71.2 | AC41: 71.3 | AD41: 71.2 | AE41: 71.2
B42: 41275 | C42: 70.4 | D42: 70.7 | E42: 70.7 | F42: 70.8 | G42: 70.6 | H42: 70.5 | I42: 70.5 | J42: 70.6 | K42: 70.7 | L42: 70.7 | M42: 70.6 | N42: 70.7 | O42: 70.6 | P42: 70.4 | Q42: 70.3 | R42: 70.2 | S42: 70.3 | T42: 70.3 | U42: 70.4 | V42: 70.4 | W42: 70.5 | X42: 70.6 | Y42: 70.7 | Z42: 70.8 | AA42: 71 | AB42: 71.2 | AC42: 71.3 | AD42: 71.2 | AE42: 71.2 | AF42: 71.4
...

Sheet revisions
B1: EMP05: Revisions triangle for Employment rate
B3: 2. Revisions to UK Employment rate
B4: This spreadsheet provides a revisions analysis for the employment rate for those aged from 16 to 64. This series was first published in August 2010.
B6: Relating to Period (three months ending) | C6: 40330 | D6: 40360 | E6: 40391 | F6: 40422 | G6: 40452 | H6: 40483 | I6: 40513 | J6: 40544 | K6: 40575 | L6: 40603 | M6: 40634 | N6: 40664 | O6: 40695 | P6: 40725 | Q6: 40756 | R6: 40787 | S6: 40817 | T6: 40848 | U6: 40878 | V6: 40909 | W6: 40940 | X6: 40969 | Y6: 41000 | Z6: 41030 | AA6: 41061 | AB6: 41091 | AC6: 41122 | AD6: 41153 | AE6: 41183 | AF6: 41214 | AG6: 41244 | AH6: 41275 | AI6: 41306 | AJ6: 41334 | AK6: 41365 | AL6: 41395 | AM6: 41426 | AN6: 41456 | AO6: 41487 | AP6: 41518 | AQ6: 41548 | AR6: 41579 | AS6: 41609 | AT6: 41640 | AU6: 41671 | AV6: 41699 | AW6: 41730 | AX6: 41760 | AY6: 41791 | AZ6: 41821 | BA6: 41852 | BB6: 41883 | BC6: 41913 | BD6: 41944 | BE6: 41974 | BF6: 42005 | BG6: 42036 | BH6: 42064 | BI6: 42095 | BJ6: 42125 | BK6: 42156 | BL6: 42186 | BM6: 42217 | BN6: 42248 | BO6: 42278 | BP6: 42309 | BQ6: 42339 | BR6: 42370 | BS6: 42401 | BT6: 42430 | BU6: 42461 | BV6: 42491 | BW6: 42522 | BX6: 42552 | BY6: 42583 | BZ6: 42614 | CA6: 42644 | CB6: 42675 | CC6: 42705 | CD6: 42736 | CE6: 42767 | CF6: 42795 | CG6: 42826 | CH6: 42856 | CI6: 42887 | CJ6: 42917 | CK6: 42948 | CL6: 42979 | CM6: 43009 | CN6: 43040 | CO6: 43070 | CP6: 43101 | CQ6: 43132 | CR6: 43160 | CS6: 43191 | CT6: 43221 | CU6: 43252 | CV6: 43282 | CW6: 43313 | CX6: 43344 | CY6: 43374 | CZ6: 43405 | DA6: 43435 | DB6: 43466 | DC6: 43497 | DD6: 43525 | DE6: 43556 | DF6: 43586 | DG6: 43617 | DH6: 43647 | DI6: 43678 | DJ6: 43709 | DK6: 43739 | DL6: 43770 | DM6: 43800 | DN6: 43831 | DO6: 43862 | DP6: 43891 | DQ6: 43922 | DR6: 43952 | DS6: 43983 | DT6: 44013 | DU6: 44044 | DV6: 44075 | DW6: 44105 | DX6: 44136 | DY6: 44166 | DZ6: 44197 | EA6: 44228 | EB6: 44256 | EC6: 44287 | ED6: 44317 | EE6: 44348 | EF6: 44378 | EG6: 44409 | EH6: 44440 | EI6: 44470 | EJ6: 44501 | EK6: 44531 | EL6: 44562 | EM6: 44593 | EN6: 44621 | EO6: 44652 | EP6: 44682 | EQ6: 44713 | ER6: 44743 | ES6: 44774 | ET6: 44805 | EU6: 44835 | EV6: 44866 | EW6: 44896 | EX6: 44927 | EY6: 44958 | EZ6: 44986 | FA6: 45017 | FB6: 45047 | FC6: 45078 | FD6: 45108 | FE6: 45139 | FF6: 45170 | FG6: 45200 | FH6: 45231 | FI6: 45261 | FJ6: 45292 | FK6: 45323 | FL6: 45352 | FM6: 45383 | FN6: 45413 | FO6: 45444 | FP6: 45474 | FQ6: 45505 | FR6: 45536 | FS6: 45566 | FT6: 45597 | FU6: 45627 | FV6: 45658 | FW6: 45689 | FX6: 45717 | FY6: 45748 | FZ6: 45778 | GA6: 45809 | GB6: 45839 | GC6: 45870 | GD6: 45901 | GE6: 45931 | GF6: 45962 | GG6: 45992
B7: Month 1 estimate | C7: 0 | D7: 0 | E7: 0 | F7: 0 | G7: 0 | H7: 0 | I7: 0 | J7: 0 | K7: 0 | L7: 0 | M7: 0 | N7: 0 | O7: 0 | P7: 0 | Q7: 0 | R7: 0 | S7: 0 | T7: 0 | U7: 0 | V7: 0 | W7: 0 | X7: 0 | Y7: 0 | Z7: 0 | AA7: 0 | AB7: 0 | AC7: 0 | AD7: 0 | AE7: 0 | AF7: 0 | AG7: 0 | AH7: 0 | AI7: 0 | AJ7: 0 | AK7: 0 | AL7: 0 | AM7: 0 | AN7: 0 | AO7: 0 | AP7: 0 | AQ7: 0 | AR7: 0 | AS7: 0 | AT7: 0 | AU7: 0 | AV7: 0 | AW7: 0 | AX7: 0 | AY7: 0 | AZ7: 0 | BA7: 0 | BB7: 0 | BC7: 0 | BD7: 0 | BE7: 0 | BF7: 0 | BG7: 0 | BH7: 0 | BI7: 0 | BJ7: 0 | BK7: 0 | BL7: 0 | BM7: 0 | BN7: 0 | BO7: 0 | BP7: 0 | BQ7: 0 | BR7: 0 | BS7: 0 | BT7: 0 | BU7: 0 | BV7: 0 | BW7: 0 | BX7: 0 | BY7: 0 | BZ7: 0 | CA7: 0 | CB7: 0 | CC7: 0 | CD7: 0 | CE7: 0 | CF7: 0 | CG7: 0 | CH7: 0 | CI7: 0 | CJ7: 0 | CK7: 0 | CL7: 0 | CM7: 0 | CN7: 0 | CO7: 0 | CP7: 0 | CQ7: 0 | CR7: 0 | CS7: 0 | CT7: 0 | CU7: 0 | CV7: 0 | CW7: 0 | CX7: 0 | CY7: 0 | CZ7: 0 | DA7: 0 | DB7: 0 | DC7: 0 | DD7: 0 | DE7: 0 | DF7: 0 | DG7: 0 | DH7: 0 | DI7: 0 | DJ7: 0 | DK7: 0 | DL7: 0 | DM7: 0 | DN7: 0 | DO7: 0 | DP7: 0 | DQ7: 0 | DR7: 0 | DS7: 0 | DT7: 0 | DU7: 0 | DV7: 0 | DW7: 0 | DX7: 0 | DY7: 0 | DZ7: 0 | EA7: 0 | EB7: 0 | EC7: 0 | ED7: 0 | EE7: 0 | EF7: 0 | EG7: 0 | EH7: 0 | EI7: 0 | EJ7: 0 | EK7: 0 | EL7: 0 | EM7: 0 | EN7: 0 | EO7: 0 | EP7: 0 | EQ7: 0 | ER7: 0 | ES7: 0 | ET7: 0 | EU7: 0 | EV7: 0 | EW7: 0 | EX7: 0 | EY7: 0 | EZ7: 0 | FA7: 0 | FB7: 0 | FC7: 0 | FD7: 0 | FE7: 0 | FF7: 0 | FG7: 0 | FH7: 0 | FI7: 0 | FJ7: 0 | FK7: 0 | FL7: 0 | FM7: 0 | FN7: 0 | FO7: 0 | FP7: 0 | FQ7: 0 | FR7: 0 | FS7: 0 | FT7: 0 | FU7: 0 | FV7: 0 | FW7: 0 | FX7: 0 | FY7: 0 | FZ7: 0 | GA7: 0 | GB7: 0 | GC7: 0 | GD7: 0 | GE7: 0 | GF7: 0 | GG7: 0
B8: Month 2 estimate | C8: 0 | D8: 0 | E8: 0 | F8: 0 | G8: 0 | H8: 0 | I8: 0 | J8: 0 | K8: 0 | L8: 0 | M8: 0 | N8: 0 | O8: 0 | P8: 0 | Q8: 0 | R8: 0 | S8: 0 | T8: 0 | U8: 0 | V8: 0 | W8: 0 | X8: 0 | Y8: 0 | Z8: 0 | AA8: 0 | AB8: 0 | AC8: 0 | AD8: 0 | AE8: 0 | AF8: 0 | AG8: 0 | AH8: 0 | AI8: 0 | AJ8: 0 | AK8: 0 | AL8: 0 | AM8: 0 | AN8: 0 | AO8: 0 | AP8: 0 | AQ8: 0 | AR8: 0 | AS8: 0 | AT8: 0 | AU8: 0 | AV8: 0 | AW8: 0 | AX8: 0 | AY8: 0 | AZ8: 0 | BA8: 0 | BB8: 0 | BC8: 0 | BD8: 0 | BE8: 0 | BF8: 0 | BG8: 0 | BH8: 0 | BI8: 0 | BJ8: 0 | BK8: 0 | BL8: 0 | BM8: 0 | BN8: 0 | BO8: 0 | BP8: 0 | BQ8: 0 | BR8: 0 | BS8: 0 | BT8: 0 | BU8: 0 | BV8: 0 | BW8: 0 | BX8: 0 | BY8: 0 | BZ8: 0 | CA8: 0 | CB8: 0 | CC8: 0 | CD8: 0 | CE8: 0 | CF8: 0 | CG8: 0 | CH8: 0 | CI8: 0 | CJ8: 0 | CK8: 0 | CL8: 0 | CM8: 0 | CN8: 0 | CO8: 0 | CP8: 0 | CQ8: 0 | CR8: 0 | CS8: 0 | CT8: 0 | CU8: 0 | CV8: 0 | CW8: 0 | CX8: 0 | CY8: 0 | CZ8: 0 | DA8: 0 | DB8: 0 | DC8: 0 | DD8: 0 | DE8: 0 | DF8: 0 | DG8: 0 | DH8: 0 | DI8: 0 | DJ8: 0 | DK8: 0 | DL8: 0 | DM8: 0 | DN8: 0 | DO8: 0 | DP8: 0 | DQ8: 0 | DR8: 0 | DS8: 0 | DT8: 0 | DU8: 0 | DV8: 0 | DW8: 0 | DX8: 0 | DY8: 0 | DZ8: 0 | EA8: 0 | EB8: 0 | EC8: 0 | ED8: 0 | EE8: 0 | EF8: 0 | EG8: 0 | EH8: 0 | EI8: 0 | EJ8: 0 | EK8: 0 | EL8: 0 | EM8: 0 | EN8: 0 | EO8: 0 | EP8: 0 | EQ8: 0 | ER8: 0 | ES8: 0 | ET8: 0 | EU8: 0 | EV8: 0 | EW8: 0 | EX8: 0 | EY8: 0 | EZ8: 0 | FA8: 0 | FB8: 0 | FC8: 0 | FD8: 0 | FE8: 0 | FF8: 0 | FG8: 0 | FH8: 0 | FI8: 0 | FJ8: 0 | FK8: 0 | FL8: 0 | FM8: 0 | FN8: 0 | FO8: 0 | FP8: 0 | FQ8: 0 | FR8: 0 | FS8: 0 | FT8: 0 | FU8: 0 | FV8: 0 | FW8: 0 | FX8: 0 | FY8: 0 | FZ8: 0 | GA8: 0 | GB8: 0 | GC8: 0 | GD8: 0 | GE8: 0 | GF8: 0 | GG8: 0
B9: First Estimate | C9: 70.5 | D9: 70.7 | E9: 70.7 | F9: 70.8 | G9: 70.6 | H9: 70.4 | I9: 70.5 | J9: 70.5 | K9: 70.7 | L9: 70.7 | M9: 70.6 | N9: 70.7 | O9: 70.7 | P9: 70.5 | Q9: 70.4 | R9: 70.2 | S9: 70.3 | T9: 70.3 | U9: 70.3 | V9: 70.3 | W9: 70.4 | X9: 70.5 | Y9: 70.6 | Z9: 70.7 | AA9: 71 | AB9: 71.2 | AC9: 71.3 | AD9: 71.2 | AE9: 71.2 | AF9: 71.4 | AG9: 71.5 | AH9: 71.5 | AI9: 71.4 | AJ9: 71.4 | AK9: 71.5 | AL9: 71.4 | AM9: 71.5 | AN9: 71.6 | AO9: 71.7 | AP9: 71.8 | AQ9: 72 | AR9: 72.1 | AS9: 72.1 | AT9: 72.3 | AU9: 72.6 | AV9: 72.7 | AW9: 72.9 | AX9: 73.1 | AY9: 73 | AZ9: 73 | BA9: 73 | BB9: 73 | BC9: 73 | BD9: 73 | BE9: 73.2 | BF9: 73.3 | BG9: 73.4 | BH9: 73.5 | BI9: 73.4 | BJ9: 73.3 | BK9: 73.4 | BL9: 73.5 | BM9: 73.6 | BN9: 73.7 | BO9: 73.9 | BP9: 74 | BQ9: 74.1 | BR9: 74.1 | BS9: 74.1 | BT9: 74.2 | BU9: 74.2 | BV9: 74.4 | BW9: 74.5 | BX9: 74.5 | BY9: 74.5 | BZ9: 74.5 | CA9: 74.4 | CB9: 74.5 | CC9: 74.6 | CD9: 74.6 | CE9: 74.6 | CF9: 74.8 | CG9: 74.8 | CH9: 74.9 | CI9: 75.1 | CJ9: 75.3 | CK9: 75.1 | CL9: 75 | CM9: 75.1 | CN9: 75.3 | CO9: 75.2 | CP9: 75.3 | CQ9: 75.4 | CR9: 75.6 | CS9: 75.6 | CT9: 75.7 | CU9: 75.6 | CV9: 75.5 | CW9: 75.5 | CX9: 75.5 | CY9: 75.7 | CZ9: 75.8 | DA9: 75.8 | DB9: 76.1 | DC9: 76.1 | DD9: 76.1 | DE9: 76.1 | DF9: 76 | DG9: 76.1 | DH9: 76.1 | DI9: 75.9 | DJ9: 76 | DK9: 76.2 | DL9: 76.3 | DM9: 76.5 | DN9: 76.5 | DO9: 76.6 | DP9: 76.6 | DQ9: 76.4 | DR9: 76.4 | DS9: 76.4 | DT9: 76.5 | DU9: 75.56054 | DV9: 75.3 | DW9: 75.2 | DX9: 75.2 | DY9: 75 | DZ9: 75 | EA9: 75.1 | EB9: 75.2 | EC9: 75.2 | ED9: 74.804889 | EE9: 75.072313 | EF9: 75.221203 | EG9: 75.304371 | EH9: 75.426779 | EI9: 75.461812 | EJ9: 75.5 | EK9: 75.5 | EL9: 75.6 | EM9: 75.485512 | EN9: 75.658527 | EO9: 75.648993 | EP9: 75.866475 | EQ9: 75.518216 | ER9: 75.4242 | ES9: 75.5 | ET9: 75.5 | EU9: 75.590937 | EV9: 75.6 | EW9: 75.630705 | EX9: 75.729704 | EY9: 75.809139 | EZ9: 75.876896 | FA9: 75.97215 | FB9: 75.973187 | FC9: 75.729763 | FD9: 75.483668 | FE9: 75.270661 | FF9: 75.443652 | FG9: 75.571136 | FH9: 75.68751 | FI9: 75.008565 | FJ9: 74.998781 | FK9: 74.487887 | FL9: 74.451316 | FM9: 74.298008 | FN9: 74.361419 | FO9: 74.517672 | FP9: 74.785861 | FQ9: 75.005738 | FR9: 74.811055 | FS9: 74.889153 | FT9: 74.841084 | FU9: 74.938223 | FV9: 75.006018 | FW9: 75.06605 | FX9: 74.999445 | FY9: 75.057705 | FZ9: 75.241221 | GA9: 75.268461 | GB9: 75.174093 | GC9: 75.063593 | GD9: 75.041595 | GE9: 74.915831 | GF9: 75.092992 | GG9: 74.959733
B10: Value 12 Months later | C10: 70.5 | D10: 70.7 | E10: 70.7 | F10: 70.8 | G10: 70.6 | H10: 70.4 | I10: 70.5 | J10: 70.5 | K10: 70.7 | L10: 70.7 | M10: 70.6 | N10: 70.7 | O10: 70.6 | P10: 70.4 | Q10: 70.3 | R10: 70.2 | S10: 70.3 | T10: 70.3 | U10: 70.4 | V10: 70.4 | W10: 70.5 | X10: 70.6 | Y10: 70.7 | Z10: 70.8 | AA10: 71 | AB10: 71.2 | AC10: 71.3 | AD10: 71.2 | AE10: 71.2 | AF10: 71.5 | AG10: 71.6 | AH10: 71.5 | AI10: 71.4 | AJ10: 71.4 | AK10: 71.5 | AL10: 71.4 | AM10: 71.5 | AN10: 71.6 | AO10: 71.5 | AP10: 71.6 | AQ10: 71.8 | AR10: 72 | AS10: 72 | AT10: 72.1 | AU10: 72.4 | AV10: 72.5 | AW10: 72.7 | AX10: 72.9 | AY10: 72.8 | AZ10: 72.8 | BA10: 73 | BB10: 73 | BC10: 73 | BD10: 73 | BE10: 73.2 | BF10: 73.3 | BG10: 73.4 | BH10: 73.5 | BI10: 73.4 | BJ10: 73.4 | BK10: 73.4 | BL10: 73.5 | BM10: 73.6 | BN10: 73.8 | BO10: 73.9 | BP10: 74 | BQ10: 74.1 | BR10: 74.1 | BS10: 74.1 | BT10: 74.2 | BU10: 74.2 | BV10: 74.4 | BW10: 74.4 | BX10: 74.5 | BY10: 74.5 | BZ10: 74.4 | CA10: 74.4 | CB10: 74.5 | CC10: 74.6 | CD10: 74.6 | CE10: 74.6 | CF10: 74.8 | CG10: 74.8 | CH10: 74.9 | CI10: 75.1 | CJ10: 75.3 | CK10: 75.1 | CL10: 75 | CM10: 75.1 | CN10: 75.3 | CO10: 75.2 | CP10: 75.3 | CQ10: 75.4 | CR10: 75.6 | CS10: 75.6 | CT10: 75.6 | CU10: 75.5 | CV10: 75.5 | CW10: 75.6 | CX10: 75.6 | CY10: 75.7 | CZ10: 75.8 | DA10: 75.8 | DB10: 76.1 | DC10: 76.1 | DD10: 76.1 | DE10: 76.1 | DF10: 75.8 | DG10: 76.1 | DH10: 76 | DI10: 75.9 | DJ10: 76 | DK10: 76.2 | DL10: 76.3 | DM10: 76.5 | DN10: 76.5 | DO10: 76.6 | DP10: 76.340152 | DQ10: 76.023623 | DR10: 75.8418 | DS10: 75.748395 | DT10: 75.62516 | DU10: 75.370426 | DV10: 75.032894 | DW10: 74.935644 | DX10: 74.948703 | DY10: 74.6539 | DZ10: 74.61004 | EA10: 74.720603 | EB10: 74.724823 | EC10: 74.692215 | ED10: 74.750852 | EE10: 75.019872 | EF10: 75.142336 | EG10: 75.242012 | EH10: 75.336738 | EI10: 75.385208 | EJ10: 75.417537 | EK10: 75.469459 | EL10: 75.431988 | EM10: 75.465306 | EN10: 75.626684 | EO10: 75.648993 | EP10: 75.866475 | EQ10: 75.518216 | ER10: 75.4242 | ES10: 75.5 | ET10: 75.5 | EU10: 75.590937 | EV10: 75.6 | EW10: 75.18609 | EX10: 75.243637 | EY10: 75.238481 | EZ10: 75.278703 | FA10: 75.43069 | FB10: 75.460293 | FC10: 75.169188 | FD10: 74.911923 | FE10: 74.744985 | FF10: 74.846469 | FG10: 74.869395 | FH10: 74.856164 | FI10: 74.84999 | FJ10: 74.659177 | FK10: 74.559012 | FL10: 74.495675 | FM10: 74.396209 | FN10: 74.407764 | FO10: 74.574397 | FP10: 74.722903 | FQ10: 74.985704 | FR10: 74.937976 | FS10: 74.902473 | FT10: 74.850935 | FU10: 74.956007 | FV10: N/A | FW10: N/A | FX10: N/A | FY10: N/A | FZ10: N/A | GA10: N/A | GB10: N/A | GC10: N/A | GD10: N/A | GE10: N/A | GF10: N/A | GG10: N/A
B11: BB1 Estimate | C11: 0 | D11: 0 | E11: 0 | F11: 0 | G11: 0 | H11: 0 | I11: 0 | J11: 0 | K11: 0 | L11: 0 | M11: 0 | N11: 0 | O11: 0 | P11: 0 | Q11: 0 | R11: 0 | S11: 0 | T11: 0 | U11: 0 | V11: 0 | W11: 0 | X11: 0 | Y11: 0 | Z11: 0 | AA11: 0 | AB11: 0 | AC11: 0 | AD11: 0 | AE11: 0 | AF11: 0 | AG11: 0 | AH11: 0 | AI11: 0 | AJ11: 0 | AK11: 0 | AL11: 0 | AM11: 0 | AN11: 0 | AO11: 0 | AP11: 0 | AQ11: 0 | AR11: 0 | AS11: 0 | AT11: 0 | AU11: 0 | AV11: 0 | AW11: 0 | AX11: 0 | AY11: 0 | AZ11: 0 | BA11: 0 | BB11: 0 | BC11: 0 | BD11: 0 | BE11: 0 | BF11: 0 | BG11: 0 | BH11: 0 | BI11: 0 | BJ11: 0 | BK11: 0 | BL11: 0 | BM11: 0 | BN11: 0 | BO11: 0 | BP11: 0 | BQ11: 0 | BR11: 0 | BS11: 0 | BT11: 0 | BU11: 0 | BV11: 0 | BW11: 0 | BX11: 0 | BY11: 0 | BZ11: 0 | CA11: 0 | CB11: 0 | CC11: 0 | CD11: 0 | CE11: 0 | CF11: 0 | CG11: 0 | CH11: 0 | CI11: 0 | CJ11: 0 | CK11: 0 | CL11: 0 | CM11: 0 | CN11: 0 | CO11: 0 | CP11: 0 | CQ11: 0 | CR11: 0 | CS11: 0 | CT11: 0 | CU11: 0 | CV11: 0 | CW11: 0 | CX11: 0 | CY11: 0 | CZ11: 0 | DA11: 0 | DB11: 0 | DC11: 0 | DD11: 0 | DE11: 0 | DF11: 0 | DG11: 0 | DH11: 0 | DI11: 0 | DJ11: 0 | DK11: 0 | DL11: 0 | DM11: 0 | DN11: 0 | DO11: 0 | DP11: 0 | DQ11: 0 | DR11: 0 | DS11: 0 | DT11: 0 | DU11: 0 | DV11: 0 | DW11: 0 | DX11: 0 | DY11: 0 | DZ11: 0 | EA11: 0 | EB11: 0 | EC11: 0 | ED11: 0 | EE11: 0 | EF11: 0 | EG11: 0 | EH11: 0 | EI11: 0 | EJ11: 0 | EK11: 0 | EL11: 0 | EM11: 0 | EN11: 0 | EO11: 0 | EP11: 0 | EQ11: 0 | ER11: 0 | ES11: 0 | ET11: 0 | EU11: 0 | EV11: 0 | EW11: 0 | EX11: 0 | EY11: 0 | EZ11: 0 | FA11: 0 | FB11: 0 | FC11: 0 | FD11: 0 | FE11: 0 | FF11: 0 | FG11: 0 | FH11: 0 | FI11: 0 | FJ11: 0 | FK11: 0 | FL11: 0 | FM11: 0 | FN11: 0 | FO11: 0 | FP11: 0 | FQ11: 0 | FR11: 0 | FS11: 0 | FT11: 0 | FU11: 0 | FV11: 0 | FW11: 0 | FX11: 0 | FY11: 0 | FZ11: 0 | GA11: 0 | GB11: 0 | GC11: 0 | GD11: 0 | GE11: 0 | GF11: 0 | GG11: 0
B12: BB2 Estimate | C12: 0 | D12: 0 | E12: 0 | F12: 0 | G12: 0 | H12: 0 | I12: 0 | J12: 0 | K12: 0 | L12: 0 | M12: 0 | N12: 0 | O12: 0 | P12: 0 | Q12: 0 | R12: 0 | S12: 0 | T12: 0 | U12: 0 | V12: 0 | W12: 0 | X12: 0 | Y12: 0 | Z12: 0 | AA12: 0 | AB12: 0 | AC12: 0 | AD12: 0 | AE12: 0 | AF12: 0 | AG12: 0 | AH12: 0 | AI12: 0 | AJ12: 0 | AK12: 0 | AL12: 0 | AM12: 0 | AN12: 0 | AO12: 0 | AP12: 0 | AQ12: 0 | AR12: 0 | AS12: 0 | AT12: 0 | AU12: 0 | AV12: 0 | AW12: 0 | AX12: 0 | AY12: 0 | AZ12: 0 | BA12: 0 | BB12: 0 | BC12: 0 | BD12: 0 | BE12: 0 | BF12: 0 | BG12: 0 | BH12: 0 | BI12: 0 | BJ12: 0 | BK12: 0 | BL12: 0 | BM12: 0 | BN12: 0 | BO12: 0 | BP12: 0 | BQ12: 0 | BR12: 0 | BS12: 0 | BT12: 0 | BU12: 0 | BV12: 0 | BW12: 0 | BX12: 0 | BY12: 0 | BZ12: 0 | CA12: 0 | CB12: 0 | CC12: 0 | CD12: 0 | CE12: 0 | CF12: 0 | CG12: 0 | CH12: 0 | CI12: 0 | CJ12: 0 | CK12: 0 | CL12: 0 | CM12: 0 | CN12: 0 | CO12: 0 | CP12: 0 | CQ12: 0 | CR12: 0 | CS12: 0 | CT12: 0 | CU12: 0 | CV12: 0 | CW12: 0 | CX12: 0 | CY12: 0 | CZ12: 0 | DA12: 0 | DB12: 0 | DC12: 0 | DD12: 0 | DE12: 0 | DF12: 0 | DG12: 0 | DH12: 0 | DI12: 0 | DJ12: 0 | DK12: 0 | DL12: 0 | DM12: 0 | DN12: 0 | DO12: 0 | DP12: 0 | DQ12: 0 | DR12: 0 | DS12: 0 | DT12: 0 | DU12: 0 | DV12: 0 | DW12: 0 | DX12: 0 | DY12: 0 | DZ12: 0 | EA12: 0 | EB12: 0 | EC12: 0 | ED12: 0 | EE12: 0 | EF12: 0 | EG12: 0 | EH12: 0 | EI12: 0 | EJ12: 0 | EK12: 0 | EL12: 0 | EM12: 0 | EN12: 0 | EO12: 0 | EP12: 0 | EQ12: 0 | ER12: 0 | ES12: 0 | ET12: 0 | EU12: 0 | EV12: 0 | EW12: 0 | EX12: 0 | EY12: 0 | EZ12: 0 | FA12: 0 | FB12: 0 | FC12: 0 | FD12: 0 | FE12: 0 | FF12: 0 | FG12: 0 | FH12: 0 | FI12: 0 | FJ12: 0 | FK12: 0 | FL12: 0 | FM12: 0 | FN12: 0 | FO12: 0 | FP12: 0 | FQ12: 0 | FR12: 0 | FS12: 0 | FT12: 0 | FU12: 0 | FV12: 0 | FW12: 0 | FX12: 0 | FY12: 0 | FZ12: 0 | GA12: 0 | GB12: 0 | GC12: 0 | GD12: 0 | GE12: 0 | GF12: 0 | GG12: 0
B13: 40391
B14: 40422 | C14: 0
B15: 40452 | C15: 0 | D15: 0
B16: 40483 | C16: 0 | D16: 0 | E16: 0
B17: 40513 | C17: 0 | D17: 0 | E17: 0 | F17: 0
B18: 40544 | C18: 0 | D18: 0 | E18: 0 | F18: 0 | G18: 0
B19: 40575 | C19: 0 | D19: 0 | E19: 0 | F19: 0 | G19: 0 | H19: 0
B20: 40603 | C20: 0 | D20: 0 | E20: 0 | F20: 0 | G20: 0 | H20: 0 | I20: 0
B21: 40634 | C21: 0 | D21: 0 | E21: 0 | F21: 0 | G21: 0 | H21: 0 | I21: 0 | J21: 0
B22: 40664 | C22: 0 | D22: 0 | E22: 0 | F22: 0 | G22: 0 | H22: 0 | I22: 0 | J22: 0 | K22: 0
B23: 40695 | C23: 0 | D23: 0 | E23: 0 | F23: 0 | G23: 0 | H23: 0 | I23: 0 | J23: 0 | K23: 0 | L23: 0
B24: 40725 | C24: 0 | D24: 0 | E24: 0 | F24: 0 | G24: 0 | H24: 0 | I24: 0 | J24: 0 | K24: 0 | L24: 0 | M24: 0
B25: 40756 | C25: 0 | D25: 0 | E25: 0 | F25: 0 | G25: 0 | H25: 0 | I25: 0 | J25: 0 | K25: 0 | L25: 0 | M25: 0 | N25: 0
B26: 40787 | C26: 0 | D26: 0 | E26: 0 | F26: 0 | G26: 0 | H26: 0 | I26: 0 | J26: 0 | K26: 0 | L26: 0 | M26: 0 | N26: 0 | O26: 0
B27: 40817 | C27: 0 | D27: 0 | E27: 0 | F27: 0 | G27: 0 | H27: 0 | I27: 0 | J27: 0 | K27: 0 | L27: 0 | M27: 0 | N27: 0 | O27: 0 | P27: 0
B28: 40848 | C28: 0 | D28: 0 | E28: 0 | F28: 0 | G28: 0 | H28: 0 | I28: 0 | J28: 0 | K28: 0 | L28: 0 | M28: 0 | N28: 0 | O28: 0 | P28: 0 | Q28: 0
B29: 40878 | C29: 0 | D29: 0 | E29: 0 | F29: 0 | G29: 0 | H29: 0 | I29: 0 | J29: 0 | K29: 0 | L29: 0 | M29: 0 | N29: 0 | O29: 0 | P29: 0 | Q29: 0 | R29: 0
B30: 40909 | C30: 0 | D30: 0 | E30: 0 | F30: 0 | G30: 0 | H30: 0 | I30: 0 | J30: 0 | K30: 0 | L30: 0 | M30: 0 | N30: 0 | O30: 0 | P30: 0 | Q30: 0 | R30: 0 | S30: 0
B31: 40940 | C31: 0 | D31: 0 | E31: 0 | F31: 0 | G31: 0 | H31: 0 | I31: 0 | J31: 0 | K31: 0 | L31: 0 | M31: 0 | N31: 0 | O31: 0 | P31: 0 | Q31: 0 | R31: 0 | S31: 0 | T31: 0
B32: 40969 | C32: 0 | D32: 0 | E32: 0 | F32: 0 | G32: 0 | H32: 0 | I32: 0 | J32: 0 | K32: 0 | L32: 0 | M32: 0 | N32: 0 | O32: 0 | P32: 0 | Q32: 0 | R32: 0 | S32: 0 | T32: 0 | U32: 0
B33: 41000 | C33: 0 | D33: 0 | E33: 0 | F33: 0 | G33: 0 | H33: 0 | I33: 0 | J33: 0 | K33: 0 | L33: 0 | M33: 0 | N33: 0 | O33: 0 | P33: 0 | Q33: 0 | R33: 0 | S33: 0 | T33: 0 | U33: 0 | V33: 0
B34: 41030 | C34: 0 | D34: 0 | E34: 0 | F34: 0 | G34: 0 | H34: 0 | I34: 0 | J34: 0 | K34: 0 | L34: 0 | M34: 0 | N34: 0 | O34: 0 | P34: 0 | Q34: 0 | R34: 0 | S34: 0 | T34: 0 | U34: 0 | V34: 0 | W34: 0
B35: 41061 | C35: 0 | D35: 0 | E35: 0 | F35: 0 | G35: 0 | H35: 0 | I35: 0 | J35: 0 | K35: 0 | L35: 0 | M35: 0 | N35: 0 | O35: 0 | P35: 0 | Q35: 0 | R35: 0 | S35: 0 | T35: 0 | U35: 0 | V35: 0 | W35: 0 | X35: 0
B36: 41091 | C36: 0 | D36: 0 | E36: 0 | F36: 0 | G36: 0 | H36: 0 | I36: 0 | J36: 0 | K36: 0 | L36: 0 | M36: 0 | N36: 0 | O36: 0 | P36: 0 | Q36: 0 | R36: 0 | S36: 0 | T36: 0 | U36: 0 | V36: 0 | W36: 0 | X36: 0 | Y36: 0
B37: 41122 | C37: -0.1 | D37: 0 | E37: 0 | F37: 0 | G37: 0 | H37: 0.1 | I37: 0 | J37: 0.1 | K37: 0 | L37: 0 | M37: 0 | N37: 0 | O37: -0.1 | P37: -0.1 | Q37: -0.1 | R37: 0 | S37: 0 | T37: 0 | U37: 0.1 | V37: 0.1 | W37: 0.1 | X37: 0.1 | Y37: 0.1 | Z37: 0.1
B38: 41153 | C38: 0 | D38: 0 | E38: 0 | F38: 0 | G38: 0 | H38: 0 | I38: 0 | J38: 0 | K38: 0 | L38: 0 | M38: 0 | N38: 0 | O38: 0 | P38: 0 | Q38: 0 | R38: 0 | S38: 0 | T38: 0 | U38: 0 | V38: 0 | W38: 0 | X38: 0 | Y38: 0 | Z38: 0 | AA38: 0
B39: 41183 | C39: 0 | D39: 0 | E39: 0 | F39: 0 | G39: 0 | H39: 0 | I39: 0 | J39: 0 | K39: 0 | L39: 0 | M39: 0 | N39: 0 | O39: 0 | P39: 0 | Q39: 0 | R39: 0 | S39: 0 | T39: 0 | U39: 0 | V39: 0 | W39: 0 | X39: 0 | Y39: 0 | Z39: 0 | AA39: 0 | AB39: 0
B40: 41214 | C40: 0 | D40: 0 | E40: 0 | F40: 0 | G40: 0 | H40: 0 | I40: 0 | J40: 0 | K40: 0 | L40: 0 | M40: 0 | N40: 0 | O40: 0 | P40: 0 | Q40: 0 | R40: 0 | S40: 0 | T40: 0 | U40: 0 | V40: 0 | W40: 0 | X40: 0 | Y40: 0 | Z40: 0 | AA40: 0 | AB40: 0 | AC40: 0
B41: 41244 | C41: 0 | D41: 0 | E41: 0 | F41: 0 | G41: 0 | H41: 0 | I41: 0 | J41: 0 | K41: 0 | L41: 0 | M41: 0 | N41: 0 | O41: 0 | P41: 0 | Q41: 0 | R41: 0 | S41: 0 | T41: 0 | U41: 0 | V41: 0 | W41: 0 | X41: 0 | Y41: 0 | Z41: 0 | AA41: 0 | AB41: 0 | AC41: 0 | AD41: 0
B42: 41275 | C42: 0 | D42: 0 | E42: 0 | F42: 0 | G42: 0 | H42: 0 | I42: 0 | J42: 0 | K42: 0 | L42: 0 | M42: 0 | N42: 0 | O42: 0 | P42: 0 | Q42: 0 | R42: 0 | S42: 0 | T42: 0 | U42: 0 | V42: 0 | W42: 0 | X42: 0 | Y42: 0 | Z42: 0 | AA42: 0 | AB42: 0 | AC42: 0 | AD42: 0 | AE42: 0
...

Sheet comments
B1: This spreadsheet provides a revisions analysis for the employment rate for those aged from 16 to 64.
B4: Comments
B7: Period Revised | C7: Publication Date | D7: Cause of Revision
B8: From 2002 | C8: 14 September 2005 | D8: To take account of the latest population estimates and the annual
D9: review of Labour Force Survey data seasonal adjustment.
B10: From 2003 | C10: 18 October 2006 | D10: Annual seasonal adjustment review and incorporating latest
D11: population estimates.
B12: From 2000 | C12: 14 November 2007 | D12: Incorporation of latest population estimates.
B13: From 1992 | C13: 14 May 2008 | D13: Reweighting of population estimates and review of seasonal
D14: adjustment.
B15: From 2006 | C15: 15 October 2008 | D15: Incorporation of latest population estimates.
D16: Annual seasonal adjustment review and incorporating latest
B17: From 2007 | C17: 11 November 2009 | D17: population estimates.
B18: From 2006 | C18: 17 February 2010 | D18: Full re-weighting of LFS population estimates.
B19: From 1992 | C19: 11 August 2010 | D19: Review of Labour Force Survey data seasonal adjustment.
B20: From 2001 | C20: 18 May 2011 | D20: Incorporation of latest population estimates.
B21: From 2009 | C21: 15 August 2012 | D21: To take account of the latest population estimates and the annual
D22: review of Labour Force Survey data seasonal adjustment.
B23: From 2001 | C23: 15 October 2014 | D23: To take account of the Census 2011 population estimates and the
D24: annual review of Labour Force Survey data seasonal adjustment.
B25: From 2012 | C25: 18 May 2016 | D25: To take account of the latest population estimates and the annual
D26: review of Labour Force Survey data seasonal adjustment.
B27: From 2012 | C27: 17 May 2017 | D27: To take account of the latest population estimates and the annual
D28: review of Labour Force Survey data seasonal adjustment.
B29: From 2011 | C29: 19 February 2019 | D29: To take account of the latest population estimates and the annual
D30: review of Labour Force Survey data seasonal adjustment.
B31: From May 2020 | C31: 44481 | D31: To take in to account the latest population estimates adjusted for non-response bias due to Covid-19 pandemic
B32: From 2020 | C32: 44392 | D32: To take in to account the latest population estimates adjusted for non-response bias due to Covid-19 pandemic
B33: From January to March 2020 | C33: 44726 | D33: Reweighting of estimates back to January to March 2020
B34: From June-August 2011 to June-August 2022 | C34: 45335 | D34: Modelling of estimates from June-August 2011 to June-August 2022 for consistency with reweighted data from July-September 2022
B35: From July-September 2022 to September-November 2023 | C35: 45335 | D35: Reweighting of estimates back to July-September 2022
B36: From June - August 2011 to December -February 2019 | C36: 45643 | D36: Modelling of estimates from June-August 2011 to December 2018-February 2019 for consistency with reweighted data from January to March 2019
B37: From January - March 2019 to July – September 2024 | C37: 45643 | D37: Reweighting of estimates back to January – March 2019
B38: From January - March 2019 to October to December 2024 | C38: 45736 | D38: Revised data due to seasonal adjustment review

Sheet after 12 Months
B1: Revisions spreadsheet for monthly data 1st Estimate after 12 Months
B2: (Please note that each worksheet in this file contains calculations for one indicator)
B3: =triangle!B6 -> Relating to Period (three months ending) | C3: First Estimate | D3: Value 12 Months later | E3: Revision | F3: r(t-1) | G3: Abs (rev) | I3: Standard t-test | K3: Adjusted t-stat
I4: n | J4: =COUNT(E6:E65) -> 60 | K4: alpha | L4: =CORREL(E6:E65,F6:F65) -> 0.77077064
I5: rbar | J5: =AVERAGE(E6:E65) -> -0.22630449 | K5: s*^2 | L5: =((1+L4)/(1-L4))*J6 -> 0.53557872
B6: =triangle!$DN$6 -> 43831 | C6: =triangle!$DN$9 -> 76.5 | D6: =triangle!$DN$10 -> 76.5 | E6: =IF(OR(C6="N/A",D6="N/A",ISBLANK(C6),ISBLANK(D6)),"",D6-C6) -> 0 | G6: =IF(ISTEXT(E6),"",ABS(E6)) -> 0 | I6: s^2 | J6: =VARP(E6:E65) -> 0.069331604 | K6: n* | L6: =ROUNDUP(N8,0) -> 16
B7: =triangle!$DO$6 -> 43862 | C7: =triangle!$DO$9 -> 76.6 | D7: =triangle!$DO$10 -> 76.6 | E7: =IF(OR(C7="N/A",D7="N/A",ISBLANK(C7),ISBLANK(D7)),"",D7-C7) -> 0 | F7: =IF(ISBLANK(E6)," ",E6) -> 0 | G7: =IF(ISTEXT(E7),"",ABS(E7)) -> 0 | I7: t | J7: =J5/SQRT(J6/J4) -> -6.6573773 | K7: t* | L7: =J5/SQRT(L5/J4) -> -2.3952847
B8: =triangle!$DP$6 -> 43891 | C8: =triangle!$DP$9 -> 76.6 | D8: =triangle!$DP$10 -> 76.340152 | E8: =IF(OR(C8="N/A",D8="N/A",ISBLANK(C8),ISBLANK(D8)),"",D8-C8) -> -0.25984839 | F8: =IF(ISBLANK(E7)," ",E7) -> 0 | G8: =IF(ISTEXT(E8),"",ABS(E8)) -> 0.25984839 | I8: t-crit | J8: =TINV(0.05,J4) -> 2.0002978 | K8: t*-crit | L8: =TINV(0.05,L6) -> 2.1199053 | M8: n* | N8: =((1-(L4^2))/(1+(L4^2)))*J4 -> 15.278182
B9: =triangle!$DQ$6 -> 43922 | C9: =triangle!$DQ$9 -> 76.4 | D9: =triangle!$DQ$10 -> 76.023623 | E9: =IF(OR(C9="N/A",D9="N/A",ISBLANK(C9),ISBLANK(D9)),"",D9-C9) -> -0.37637667 | F9: =IF(ISBLANK(E8)," ",E8) -> -0.25984839 | G9: =IF(ISTEXT(E9),"",ABS(E9)) -> 0.37637667 | I9: significant or not? | J9: =IF(ABS(J7)>J8,"Yes", "No") -> Yes | K9: significant or not? | L9: =IF(ABS(L7)>L8,"Yes", "No") -> Yes
B10: =triangle!$DR$6 -> 43952 | C10: =triangle!$DR$9 -> 76.4 | D10: =triangle!$DR$10 -> 75.8418 | E10: =IF(OR(C10="N/A",D10="N/A",ISBLANK(C10),ISBLANK(D10)),"",D10-C10) -> -0.55819997 | F10: =IF(ISBLANK(E9)," ",E9) -> -0.37637667 | G10: =IF(ISTEXT(E10),"",ABS(E10)) -> 0.55819997
B11: =triangle!$DS$6 -> 43983 | C11: =triangle!$DS$9 -> 76.4 | D11: =triangle!$DS$10 -> 75.748395 | E11: =IF(OR(C11="N/A",D11="N/A",ISBLANK(C11),ISBLANK(D11)),"",D11-C11) -> -0.65160513 | F11: =IF(ISBLANK(E10)," ",E10) -> -0.55819997 | G11: =IF(ISTEXT(E11),"",ABS(E11)) -> 0.65160513 | I11: Test for bias | K11: Mean Revision = | L11: =AVERAGE(E6:E65) -> -0.22630449
B12: =triangle!$DT$6 -> 44013 | C12: =triangle!$DT$9 -> 76.5 | D12: =triangle!$DT$10 -> 75.62516 | E12: =IF(OR(C12="N/A",D12="N/A",ISBLANK(C12),ISBLANK(D12)),"",D12-C12) -> -0.87484049 | F12: =IF(ISBLANK(E11)," ",E11) -> -0.65160513 | G12: =IF(ISTEXT(E12),"",ABS(E12)) -> 0.87484049 | I12: Which test to use | J12: =IF(L4<0,"Standard","Adjusted") -> Adjusted | K12: Abs av rev = | L12: =AVERAGE(G6:G65) -> 0.24245885
B13: =triangle!$DU$6 -> 44044 | C13: =triangle!$DU$9 -> 75.56054 | D13: =triangle!$DU$10 -> 75.370426 | E13: =IF(OR(C13="N/A",D13="N/A",ISBLANK(C13),ISBLANK(D13)),"",D13-C13) -> -0.19011436 | F13: =IF(ISBLANK(E12)," ",E12) -> -0.87484049 | G13: =IF(ISTEXT(E13),"",ABS(E13)) -> 0.19011436 | I13: Is test significant? | J13: =IF(L4<0,J9,L9) -> Yes | K13: Is test significant? | L13: =IF(L4<0,J9,L9) -> Yes
B14: =triangle!$DV$6 -> 44075 | C14: =triangle!$DV$9 -> 75.3 | D14: =triangle!$DV$10 -> 75.032894 | E14: =IF(OR(C14="N/A",D14="N/A",ISBLANK(C14),ISBLANK(D14)),"",D14-C14) -> -0.26710644 | F14: =IF(ISBLANK(E13)," ",E13) -> -0.19011436 | G14: =IF(ISTEXT(E14),"",ABS(E14)) -> 0.26710644
B15: =triangle!$DW$6 -> 44105 | C15: =triangle!$DW$9 -> 75.2 | D15: =triangle!$DW$10 -> 74.935644 | E15: =IF(OR(C15="N/A",D15="N/A",ISBLANK(C15),ISBLANK(D15)),"",D15-C15) -> -0.26435608 | F15: =IF(ISBLANK(E14)," ",E14) -> -0.26710644 | G15: =IF(ISTEXT(E15),"",ABS(E15)) -> 0.26435608
B16: =triangle!$DX$6 -> 44136 | C16: =triangle!$DX$9 -> 75.2 | D16: =triangle!$DX$10 -> 74.948703 | E16: =IF(OR(C16="N/A",D16="N/A",ISBLANK(C16),ISBLANK(D16)),"",D16-C16) -> -0.25129691 | F16: =IF(ISBLANK(E15)," ",E15) -> -0.26435608 | G16: =IF(ISTEXT(E16),"",ABS(E16)) -> 0.25129691
B17: =triangle!$DY$6 -> 44166 | C17: =triangle!$DY$9 -> 75 | D17: =triangle!$DY$10 -> 74.6539 | E17: =IF(OR(C17="N/A",D17="N/A",ISBLANK(C17),ISBLANK(D17)),"",D17-C17) -> -0.34609983 | F17: =IF(ISBLANK(E16)," ",E16) -> -0.25129691 | G17: =IF(ISTEXT(E17),"",ABS(E17)) -> 0.34609983
B18: =triangle!$DZ$6 -> 44197 | C18: =triangle!$DZ$9 -> 75 | D18: =triangle!$DZ$10 -> 74.61004 | E18: =IF(OR(C18="N/A",D18="N/A",ISBLANK(C18),ISBLANK(D18)),"",D18-C18) -> -0.38996016 | F18: =IF(ISBLANK(E17)," ",E17) -> -0.34609983 | G18: =IF(ISTEXT(E18),"",ABS(E18)) -> 0.38996016
B19: =triangle!$EA$6 -> 44228 | C19: =triangle!$EA$9 -> 75.1 | D19: =triangle!$EA$10 -> 74.720603 | E19: =IF(OR(C19="N/A",D19="N/A",ISBLANK(C19),ISBLANK(D19)),"",D19-C19) -> -0.37939696 | F19: =IF(ISBLANK(E18)," ",E18) -> -0.38996016 | G19: =IF(ISTEXT(E19),"",ABS(E19)) -> 0.37939696
B20: =triangle!$EB$6 -> 44256 | C20: =triangle!$EB$9 -> 75.2 | D20: =triangle!$EB$10 -> 74.724823 | E20: =IF(OR(C20="N/A",D20="N/A",ISBLANK(C20),ISBLANK(D20)),"",D20-C20) -> -0.4751772 | F20: =IF(ISBLANK(E19)," ",E19) -> -0.37939696 | G20: =IF(ISTEXT(E20),"",ABS(E20)) -> 0.4751772
B21: =triangle!$EC$6 -> 44287 | C21: =triangle!$EC$9 -> 75.2 | D21: =triangle!$EC$10 -> 74.692215 | E21: =IF(OR(C21="N/A",D21="N/A",ISBLANK(C21),ISBLANK(D21)),"",D21-C21) -> -0.50778482 | F21: =IF(ISBLANK(E20)," ",E20) -> -0.4751772 | G21: =IF(ISTEXT(E21),"",ABS(E21)) -> 0.50778482
B22: =triangle!$ED$6 -> 44317 | C22: =triangle!$ED$9 -> 74.804889 | D22: =triangle!$ED$10 -> 74.750852 | E22: =IF(OR(C22="N/A",D22="N/A",ISBLANK(C22),ISBLANK(D22)),"",D22-C22) -> -0.054036221 | F22: =IF(ISBLANK(E21)," ",E21) -> -0.50778482 | G22: =IF(ISTEXT(E22),"",ABS(E22)) -> 0.054036221
B23: =triangle!$EE$6 -> 44348 | C23: =triangle!$EE$9 -> 75.072313 | D23: =triangle!$EE$10 -> 75.019872 | E23: =IF(OR(C23="N/A",D23="N/A",ISBLANK(C23),ISBLANK(D23)),"",D23-C23) -> -0.052440104 | F23: =IF(ISBLANK(E22)," ",E22) -> -0.054036221 | G23: =IF(ISTEXT(E23),"",ABS(E23)) -> 0.052440104
B24: =triangle!$EF$6 -> 44378 | C24: =triangle!$EF$9 -> 75.221203 | D24: =triangle!$EF$10 -> 75.142336 | E24: =IF(OR(C24="N/A",D24="N/A",ISBLANK(C24),ISBLANK(D24)),"",D24-C24) -> -0.078866545 | F24: =IF(ISBLANK(E23)," ",E23) -> -0.052440104 | G24: =IF(ISTEXT(E24),"",ABS(E24)) -> 0.078866545
B25: =triangle!$EG$6 -> 44409 | C25: =triangle!$EG$9 -> 75.304371 | D25: =triangle!$EG$10 -> 75.242012 | E25: =IF(OR(C25="N/A",D25="N/A",ISBLANK(C25),ISBLANK(D25)),"",D25-C25) -> -0.062358227 | F25: =IF(ISBLANK(E24)," ",E24) -> -0.078866545 | G25: =IF(ISTEXT(E25),"",ABS(E25)) -> 0.062358227
B26: =triangle!$EH$6 -> 44440 | C26: =triangle!$EH$9 -> 75.426779 | D26: =triangle!$EH$10 -> 75.336738 | E26: =IF(OR(C26="N/A",D26="N/A",ISBLANK(C26),ISBLANK(D26)),"",D26-C26) -> -0.090041077 | F26: =IF(ISBLANK(E25)," ",E25) -> -0.062358227 | G26: =IF(ISTEXT(E26),"",ABS(E26)) -> 0.090041077
